Workbook

Sheet Hướng dẫn
A1: CHECKLIST NGHIỆM THU HỆ THỐNG ERP-CRM
A2: Kiểm thử theo workflow của từng phòng ban. Mỗi dòng là một tình huống: thao tác → kết quả mong đợi → người test ghi kết quả thực tế.
A4: 1. Cách làm
A5: Bước 1 | B5: Đọc sheet "Workflow" phần của phòng mình để hiểu thứ tự công việc, ai làm, vào menu nào.
A6: Bước 2 | B6: Mở sheet của phòng mình (1. Sales … 8. Liên phòng ban). Làm lần lượt từng dòng, đăng nhập đúng tài khoản ghi ở dòng 2 của sheet.
A7: Bước 3 | B7: Thực hiện cột "Tình huống / Thao tác", so với cột "Kết quả mong đợi", rồi điền các cột nền vàng.
A8: Bước 4 | B8: Khi xong, xem sheet "Tổng hợp" (tự đếm), trưởng phòng ghi kết luận và ký.
A10: 2. Các cột cần điền (nền vàng)
A11: Người test / Ngày test | B11: Tên người thực hiện và ngày test (dd/mm/yyyy).
A12: Kết quả | B12: Chọn trong danh sách: • Đạt – hệ thống chạy đúng như cột Kết quả mong đợi. • Không đạt – chạy khác mong đợi (sai số liệu, không chặn khi phải chặn, lỗi trang, sai thông báo, sai người nhận thông báo…). • Bị chặn – không test được vì bước trước lỗi hoặc thiếu dữ liệu / quyền. • Chưa test – để trống cũng tính là chưa test.
A13: Kết quả thực tế / Mô tả lỗi | B13: BẮT BUỘC khi Không đạt hoặc Bị chặn (ô sẽ tô đỏ nếu bỏ trống). Ghi rõ 3 ý: đã làm gì (dữ liệu nhập) – hệ thống phản hồi gì – sai ở chỗ nào so với mong đợi.
A14: Mức độ lỗi | B14: • Nghiêm trọng – sai tiền, sai tồn kho, mất dữ liệu, không làm tiếp được nghiệp vụ. • Cao – chức năng chính sai nhưng có cách làm tạm. • Trung bình – sai phụ, hiển thị sai, thông báo không rõ. • Thấp – chính tả, giao diện, góp ý.
A15: Bằng chứng | B15: Tên file ảnh chụp màn hình / link, mã chứng từ liên quan (mã báo giá, SO, PO, phiếu…), tài khoản đã dùng.
A16: Dev phản hồi / Trạng thái xử lý | B16: Đội phát triển ghi nguyên nhân, cách sửa và cập nhật trạng thái: Mới → Đang sửa → Đã sửa – chờ test lại → Test lại đạt (hoặc Không sửa kèm lý do). Người test kiểm lại rồi đổi Kết quả.
A17: Ghi chú | B17: Ý kiến khác, đề xuất cải tiến.
A19: 3. Ví dụ một dòng Không đạt (ghi theo mẫu này)
A20: Mã TC | B20: SAL-003
A21: Tình huống / Thao tác | B21: Tạo khách có MST trùng với khách đã có
A22: Kết quả mong đợi | B22: Báo lỗi trùng MST, không tạo bản ghi mới
A23: Kết quả | B23: Không đạt
A24: Kết quả thực tế / Mô tả lỗi | B24: Nhập khách "Công ty ABC 2" với MST 0101234567 (đã có ở "Công ty ABC"). Hệ thống báo "Khách hàng đã được tạo thành công" và danh sách có 2 khách cùng MST. Mong đợi phải chặn và báo trùng MST.
A25: Mức độ lỗi | B25: Cao
A26: Bằng chứng | B26: loi_SAL-003.png; tài khoản sales01
A28: 4. Màu trong file
A29: Nền vàng | B29: Ô người test / dev điền.
A30: Nền xám | B30: Dòng tình huống phát sinh (thiếu dữ liệu, sai dữ liệu, bị từ chối, sai quyền…). Nền trắng là luồng chính.
A31: Dòng xanh nhạt | B31: Tên bước workflow, khớp số bước trong sheet Workflow.
A32: Ô đỏ | B32: Đã chọn Không đạt / Bị chặn nhưng chưa ghi mô tả lỗi hoặc mức độ.
A34: 5. Chuẩn bị trước khi test
A35: Tài khoản | B35: Mỗi vai trò một tài khoản riêng: sales_staff, sales_manager, purchase_staff, purchase_manager, warehouse_staff, warehouse_manager, accountant, technical_engineer (2), technical_lead, marketing, legal_team, order_management, director, admin / super_admin, và 1 tài khoản không có quyền.
A36: Dữ liệu mẫu | B36: 1 khách hàng có sẵn + 1 khách chưa có trong hệ thống; 2 nhà cung cấp; 3 sản phẩm (1 có S/N, 1 không S/N, 1 license); 2 kho (có 1 Kho runrate); 1 bảng giá bán; 1 bảng giá NCC; 1 mẫu tiến độ thanh toán; tỷ giá USD ngày test.
A37: Kiểm ở mọi bước | B37: Thông báo (chuông + email) đến đúng người; badge sidebar tăng / giảm đúng; nhật ký ghi lại người thao tác; người không có quyền không thấy nút và bị chặn khi gọi thẳng URL.

Sheet Tổng hợp
A1: TỔNG HỢP KẾT QUẢ NGHIỆM THU (tự tính từ các sheet phòng ban)
A3: Phòng ban | B3: Sheet | C3: Tổng TC | D3: Đạt | E3: Không đạt | F3: Bị chặn | G3: Chưa test | H3: % đã test | I3: % đạt (trên số đã test) | J3: Lỗi Nghiêm trọng | K3: Lỗi Cao | L3: Trưởng phòng nghiệm thu | M3: Ngày ký | N3: Kết luận | O3: Ghi chú / điều kiện
A4: Kinh doanh (Sales) | B4: 1. Sales | C4: =COUNTIF('1. Sales'!$A$6:$A$600,"SAL-*") -> 98 | D4: =COUNTIF('1. Sales'!$I$6:$I$600,"Đạt") -> 0 | E4: =COUNTIF('1. Sales'!$I$6:$I$600,"Không đạt") -> 0 | F4: =COUNTIF('1. Sales'!$I$6:$I$600,"Bị chặn") -> 0 | G4: =C4-D4-E4-F4 -> 98 | H4: =IF(C4=0,0,(D4+E4+F4)/C4) -> 0 | I4: =IF(D4+E4=0,0,D4/(D4+E4)) -> 0 | J4: =COUNTIFS('1. Sales'!$I$6:$I$600,"Không đạt",'1. Sales'!$K$6:$K$600,"Nghiêm trọng") -> 0 | K4: =COUNTIFS('1. Sales'!$I$6:$I$600,"Không đạt",'1. Sales'!$K$6:$K$600,"Cao") -> 0
A5: Mua hàng (PO Team) | B5: 2. Mua hàng | C5: =COUNTIF('2. Mua hàng'!$A$6:$A$600,"PUR-*") -> 43 | D5: =COUNTIF('2. Mua hàng'!$I$6:$I$600,"Đạt") -> 0 | E5: =COUNTIF('2. Mua hàng'!$I$6:$I$600,"Không đạt") -> 0 | F5: =COUNTIF('2. Mua hàng'!$I$6:$I$600,"Bị chặn") -> 0 | G5: =C5-D5-E5-F5 -> 43 | H5: =IF(C5=0,0,(D5+E5+F5)/C5) -> 0 | I5: =IF(D5+E5=0,0,D5/(D5+E5)) -> 0 | J5: =COUNTIFS('2. Mua hàng'!$I$6:$I$600,"Không đạt",'2. Mua hàng'!$K$6:$K$600,"Nghiêm trọng") -> 0 | K5: =COUNTIFS('2. Mua hàng'!$I$6:$I$600,"Không đạt",'2. Mua hàng'!$K$6:$K$600,"Cao") -> 0
A6: Kho | B6: 3. Kho | C6: =COUNTIF('3. Kho'!$A$6:$A$600,"WH-*") -> 58 | D6: =COUNTIF('3. Kho'!$I$6:$I$600,"Đạt") -> 0 | E6: =COUNTIF('3. Kho'!$I$6:$I$600,"Không đạt") -> 0 | F6: =COUNTIF('3. Kho'!$I$6:$I$600,"Bị chặn") -> 0 | G6: =C6-D6-E6-F6 -> 58 | H6: =IF(C6=0,0,(D6+E6+F6)/C6) -> 0 | I6: =IF(D6+E6=0,0,D6/(D6+E6)) -> 0 | J6: =COUNTIFS('3. Kho'!$I$6:$I$600,"Không đạt",'3. Kho'!$K$6:$K$600,"Nghiêm trọng") -> 0 | K6: =COUNTIFS('3. Kho'!$I$6:$I$600,"Không đạt",'3. Kho'!$K$6:$K$600,"Cao") -> 0
A7: Kế toán – Tài chính | B7: 4. Kế toán | C7: =COUNTIF('4. Kế toán'!$A$6:$A$600,"ACC-*") -> 28 | D7: =COUNTIF('4. Kế toán'!$I$6:$I$600,"Đạt") -> 0 | E7: =COUNTIF('4. Kế toán'!$I$6:$I$600,"Không đạt") -> 0 | F7: =COUNTIF('4. Kế toán'!$I$6:$I$600,"Bị chặn") -> 0 | G7: =C7-D7-E7-F7 -> 28 | H7: =IF(C7=0,0,(D7+E7+F7)/C7) -> 0 | I7: =IF(D7+E7=0,0,D7/(D7+E7)) -> 0 | J7: =COUNTIFS('4. Kế toán'!$I$6:$I$600,"Không đạt",'4. Kế toán'!$K$6:$K$600,"Nghiêm trọng") -> 0 | K7: =COUNTIFS('4. Kế toán'!$I$6:$I$600,"Không đạt",'4. Kế toán'!$K$6:$K$600,"Cao") -> 0
A8: Kỹ thuật | B8: 5. Kỹ thuật | C8: =COUNTIF('5. Kỹ thuật'!$A$6:$A$600,"TEC-*") -> 28 | D8: =COUNTIF('5. Kỹ thuật'!$I$6:$I$600,"Đạt") -> 0 | E8: =COUNTIF('5. Kỹ thuật'!$I$6:$I$600,"Không đạt") -> 0 | F8: =COUNTIF('5. Kỹ thuật'!$I$6:$I$600,"Bị chặn") -> 0 | G8: =C8-D8-E8-F8 -> 28 | H8: =IF(C8=0,0,(D8+E8+F8)/C8) -> 0 | I8: =IF(D8+E8=0,0,D8/(D8+E8)) -> 0 | J8: =COUNTIFS('5. Kỹ thuật'!$I$6:$I$600,"Không đạt",'5. Kỹ thuật'!$K$6:$K$600,"Nghiêm trọng") -> 0 | K8: =COUNTIFS('5. Kỹ thuật'!$I$6:$I$600,"Không đạt",'5. Kỹ thuật'!$K$6:$K$600,"Cao") -> 0
A9: Marketing | B9: 6. Marketing | C9: =COUNTIF('6. Marketing'!$A$6:$A$600,"MKT-*") -> 23 | D9: =COUNTIF('6. Marketing'!$I$6:$I$600,"Đạt") -> 0 | E9: =COUNTIF('6. Marketing'!$I$6:$I$600,"Không đạt") -> 0 | F9: =COUNTIF('6. Marketing'!$I$6:$I$600,"Bị chặn") -> 0 | G9: =C9-D9-E9-F9 -> 23 | H9: =IF(C9=0,0,(D9+E9+F9)/C9) -> 0 | I9: =IF(D9+E9=0,0,D9/(D9+E9)) -> 0 | J9: =COUNTIFS('6. Marketing'!$I$6:$I$600,"Không đạt",'6. Marketing'!$K$6:$K$600,"Nghiêm trọng") -> 0 | K9: =COUNTIFS('6. Marketing'!$I$6:$I$600,"Không đạt",'6. Marketing'!$K$6:$K$600,"Cao") -> 0
A10: BOD & Quản trị hệ thống | B10: 7. BOD - Quản trị | C10: =COUNTIF('7. BOD - Quản trị'!$A$6:$A$600,"ADM-*") -> 30 | D10: =COUNTIF('7. BOD - Quản trị'!$I$6:$I$600,"Đạt") -> 0 | E10: =COUNTIF('7. BOD - Quản trị'!$I$6:$I$600,"Không đạt") -> 0 | F10: =COUNTIF('7. BOD - Quản trị'!$I$6:$I$600,"Bị chặn") -> 0 | G10: =C10-D10-E10-F10 -> 30 | H10: =IF(C10=0,0,(D10+E10+F10)/C10) -> 0 | I10: =IF(D10+E10=0,0,D10/(D10+E10)) -> 0 | J10: =COUNTIFS('7. BOD - Quản trị'!$I$6:$I$600,"Không đạt",'7. BOD - Quản trị'!$K$6:$K$600,"Nghiêm trọng") -> 0 | K10: =COUNTIFS('7. BOD - Quản trị'!$I$6:$I$600,"Không đạt",'7. BOD - Quản trị'!$K$6:$K$600,"Cao") -> 0
A11: Liên phòng ban (end-to-end) | B11: 8. Liên phòng ban | C11: =COUNTIF('8. Liên phòng ban'!$A$6:$A$600,"E2E-*") -> 8 | D11: =COUNTIF('8. Liên phòng ban'!$I$6:$I$600,"Đạt") -> 0 | E11: =COUNTIF('8. Liên phòng ban'!$I$6:$I$600,"Không đạt") -> 0 | F11: =COUNTIF('8. Liên phòng ban'!$I$6:$I$600,"Bị chặn") -> 0 | G11: =C11-D11-E11-F11 -> 8 | H11: =IF(C11=0,0,(D11+E11+F11)/C11) -> 0 | I11: =IF(D11+E11=0,0,D11/(D11+E11)) -> 0 | J11: =COUNTIFS('8. Liên phòng ban'!$I$6:$I$600,"Không đạt",'8. Liên phòng ban'!$K$6:$K$600,"Nghiêm trọng") -> 0 | K11: =COUNTIFS('8. Liên phòng ban'!$I$6:$I$600,"Không đạt",'8. Liên phòng ban'!$K$6:$K$600,"Cao") -> 0
A12: TỔNG CỘNG | C12: =SUM(C4:C11) -> 316 | D12: =SUM(D4:D11) -> 0 | E12: =SUM(E4:E11) -> 0 | F12: =SUM(F4:F11) -> 0 | G12: =SUM(G4:G11) -> 316 | H12: =IF(C12=0,0,(D12+E12+F12)/C12) -> 0 | I12: =IF(D12+E12=0,0,D12/(D12+E12)) -> 0 | J12: =SUM(J4:J11) -> 0 | K12: =SUM(K4:K11) -> 0
A14: Quy ước kết luận:
A15: • Đạt: mọi dòng đã test, không còn lỗi Nghiêm trọng / Cao chưa sửa.
A16: • Đạt có điều kiện: còn lỗi Trung bình / Thấp — ghi danh sách mã TC và hạn sửa vào cột Ghi chú.
A17: • Không đạt: còn lỗi Nghiêm trọng / Cao, hoặc còn dòng Bị chặn / Chưa test ở luồng chính.

Sheet Workflow
A1: WORKFLOW CHI TIẾT TỪNG PHÒNG BAN – đọc trước khi test
A3: PHÒNG KINH DOANH (SALES)
A4: Sales là điểm bắt đầu của mọi đơn hàng: tạo khách hàng, báo giá và đơn hàng bán (SO). Từ SO, hệ thống chuyển việc lần lượt sang Admin, Mua hàng, Kho, Kế toán. Sales không tự đặt hàng hay xuất kho, nhưng phải gửi yêu cầu và theo dõi đến khi khách trả đủ tiền.
A5: Bước | B5: Ai làm | C5: Vào đâu (menu) | D5: Việc cần làm | E5: Kết quả / trạng thái / chuyển cho ai
A6: 1 | B6: Sales | C6: Master Data › Khách hàng | D6: Tạo khách hàng (tên, MST không trùng, ngành, địa chỉ) và ít nhất 1 người liên hệ (P.I.C) có tên, SĐT, email. | E6: Khách xuất hiện trong ô tìm khách ở Cơ hội, Đăng ký dự án, Báo giá. Đang lập báo giá mà chưa có khách thì dùng nút "Thêm khách hàng nhanh" trên form báo giá.
A7: 2 | B7: Sales, người được mời, BOD/Manager, Marketing | C7: Bán hàng › Cơ hội | D7: Ghi nhận hoạt động gặp khách (gặp, demo, trình bày giải pháp...), mức tiềm năng 25–90%, mời người tham gia; khai quà tặng nếu cần, tạo ticket Kỹ thuật nếu cần kỹ sư đi cùng. | E7: Nháp → Đã lên lịch → Đã xác nhận → Đang thực hiện → Đã hoàn thành (hoặc Hoãn / Hủy). Chỉ hoàn thành được khi BOD đã xác nhận và ticket MKT/Kỹ thuật đi kèm đã xong. Cơ hội chín muồi → chuyển thành dự án.
A8: 3 | B8: Sales → PM/PO Team | C8: Bán hàng › Đăng ký dự án | D8: Đăng ký dự án với Hãng: khách, Hãng, BOM hoặc file BOM (bắt buộc), giá trị dự kiến; dự án Fortinet nhập thêm Net to FTN. | E8: Mới đăng ký → Đang xử lý tiếp nhận → Đã gửi Hãng → Hãng đã báo giá/duyệt → Đã đăng ký – Đang theo đuổi → Closed Won / Lost. Nhánh: Thiếu thông tin, Dự án trùng, Hãng từ chối.
A9: 4 | B9: Sales | C9: Bán hàng › Báo giá › Tạo mới | D9: Nhập khách + P.I.C, dự án (nếu có, tải nhanh BOM), tiêu đề, ngày & hạn báo giá, sản phẩm, số lượng, đơn giá, chiết khấu, VAT, tiền tệ, điều khoản. Gửi khách bằng PDF / Excel / email. | E9: Nháp → Đã gửi khách → KH chốt giá (hoặc Khách từ chối). Quá hạn chưa chốt → Hết hạn, muốn báo lại thì Nhân bản.
A10: 5 | B10: Sales | C10: Báo giá › Chuyển đơn hàng | D10: Trên báo giá đã chốt, bấm Chuyển đơn hàng. | E10: Sinh SO mã SO-YYYYMMDD-xxxx mang theo khách, sản phẩm, giá. Có dự án → "Bán theo dự án", không → "Bán lẻ". Báo giá bị khóa.
A11: 6 | B11: Sales → người duyệt (BOD) | C11: Bán hàng › Đơn hàng bán › mở SO | D11: Lập P&L (giá vốn, chi phí, margin), tiến độ thanh toán (đợt trước đặt hàng / trước xuất hàng / sau giao hàng), P.I.C phụ; bấm Gửi duyệt P&L. | E11: P&L: Nháp → Chờ duyệt → Đã duyệt (hoặc Yêu cầu chỉnh sửa / Từ chối). Sau khi gửi, SO bị khóa; muốn sửa đơn đã duyệt phải xin mở lại P&L.
A12: 7 | B12: Sales → Admin → PO Team | C12: SO › Tạo yêu cầu đặt hàng (danh sách: Bán hàng › Yêu cầu đặt hàng) | D12: Nhập Hãng, loại đơn, dòng cần đặt, POS-ID, End User (nếu cần CQ), S/N (Trade-up), file đính kèm bắt buộc. Hàng có sẵn ở Kho runrate thì tạo yêu cầu giữ hàng thay vì đặt. | E12: Bản nháp → Chờ Admin duyệt → Đã gửi → Đang xử lý → Hoàn thành. Có thể bị trả về "Thiếu thông tin" hoặc trả về sửa P&L.
A13: 8 | B13: Sales | C13: Bán hàng › Theo dõi hàng về | D13: Theo dõi tiến độ đặt hàng và hàng về; tải license nếu có. | E13: Chờ đặt hàng → Đã đặt hàng → Chờ hàng về (ETD, ETA) → Hàng đã về. PO bị Hold thì Sales nhận thông báo kèm lý do.
A14: 9 | B14: Sales → Admin → Kế toán → Kho | C14: SO | D14: Tạo yêu cầu xuất hóa đơn (chọn cần HĐ nháp hay xuất trực tiếp); gửi đề xuất xuất kho (được xuất một phần); cập nhật ngày giao hàng. | E14: Phiếu xuất: Chờ Admin duyệt xuất → Chờ KT xuất HĐ → Kho xuất thực tế. Ngày giao là mốc tính hạn các đợt "sau giao hàng".
A15: 10 | B15: Sales → Kế toán (BOD nếu ngoại lệ) | C15: SO › Tiến độ thanh toán | D15: Upload UNC cho từng đợt khi khách chuyển khoản; xin duyệt ngoại lệ nếu khách muốn đặt/xuất trước khi trả. | E15: Kế toán xác nhận → đợt Đã thanh toán, công nợ giảm, bước bị khóa được mở. Giao đủ + HĐ đủ + thu đủ → SO Hoàn thành.
A16: 11 | B16: Mọi nhân viên | C16: Bán hàng › Đặt phòng họp | D16: Chọn phòng, ngày, giờ, tiêu đề, người tham dự. | E16: Người được mời nhận lời mời và phản hồi; hệ thống chặn đặt trùng giờ.
A17: 12 | B17: Sales / Sales Manager | C17: Bán hàng › Báo cáo tần suất gặp, Báo cáo bán hàng, Công nợ khách hàng | D17: Xem số lần gặp khách theo Sales, doanh thu / margin theo kỳ, công nợ khách của mình. | E17: Số liệu khớp cơ hội và đơn hàng thực tế.
A19: PHÒNG MUA HÀNG (PO TEAM)
A20: Mua hàng biến yêu cầu đặt hàng của Sales thành đơn đặt Hãng / NCC (PO), theo dõi hàng trên đường về và xác nhận hàng đã nhận. Một PO có thể gom hàng của nhiều SO cùng Hãng. Khi PO nhận hàng, hệ thống tự tạo phiếu nhập kho cho Kho.
A21: Bước | B21: Ai làm | C21: Vào đâu (menu) | D21: Việc cần làm | E21: Kết quả / trạng thái / chuyển cho ai
A22: 1 | B22: PO Team | C22: Master Data › Nhà cung cấp; Mua hàng › Bảng giá | D22: Tạo NCC (mã, tên, MST, email, người liên hệ + chức vụ), cấu hình mẫu PO. Import bảng giá Hãng, khai chiết khấu, xem trước và áp giá vào danh mục sản phẩm. | E22: Sales tra được giá khi báo giá; NCC dùng được khi tạo PO / hỏi giá.
A23: 2 | B23: PO Team | C23: Mua hàng › Duyệt yêu cầu (PR) | D23: Kiểm tra yêu cầu đặt hàng Sales đã được Admin duyệt ("Đã gửi"): Hãng, mã SP, End User, file. | E23: Đủ → "Đang xử lý", dòng vào danh sách cần đặt. Thiếu → trả "Thiếu thông tin" hoặc trả Sales sửa P&L.
A24: 3 | B24: PO Team | C24: Mua hàng › Gom đơn cần đặt | D24: Chọn các dòng cùng Hãng → tạo PO nháp; gộp PO nháp cùng Hãng; kiểm tra mã PO, giá, điều khoản thanh toán. Không đặt được thì báo Sales / hủy dòng kèm lý do. | E24: PO nháp "Chờ đặt". Hủy dòng → P&L của SO mở lại cho Sales.
A25: 4 | B25: PO Team → purchase_manager | C25: Mua hàng › Đặt hàng với hãng (PO) | D25: Xác nhận PO nháp, gửi duyệt. | E25: Chờ đặt → Chờ duyệt → Đã đặt. Bị chặn nếu SO chưa thu đợt "trước đặt hàng". Sales của SO nhận thông báo.
A26: 5 | B26: PO Team | C26: Mua hàng › Đặt hàng với hãng (PO) › mở PO | D26: Gửi PO qua email cho NCC; xác nhận khi Hãng xác nhận; cập nhật ETD, ETA, mã vận đơn; chuyển "Đang về"; upload license. Sự cố: Hold, trả về Gom đơn, hủy PO. | E26: Sales thấy mốc ETD/ETA ở Theo dõi hàng về.
A27: 6 | B27: PO Team | C27: PO › Nhận hàng | D27: Nhận từng dòng / một phần / tất cả; nhập S/N (import file hoặc gõ tay). | E27: PO "Đang về (một phần)" / "Đã về – đủ hàng"; phiếu nhập kho tự sinh cho Kho; Sales được báo.
A28: 7 | B28: PO Team / BOD | C28: Mua hàng › Báo cáo mua hàng | D28: Xem giá trị mua theo NCC / kỳ, xuất Excel. | E28: Số liệu khớp các PO trong kỳ.
A30: KHO
A31: Kho giữ số liệu tồn thật: mọi thiết bị theo dõi theo kho, Số PO và S/N. Phiếu nhập sinh từ PO của Mua hàng, phiếu xuất sinh từ đề xuất của Sales. Việc của Kho là kiểm hàng, ghi đúng S/N và bấm duyệt — chỉ khi Kho duyệt thì tồn mới tăng / giảm. Kho runrate là kho hàng có sẵn, Sales được xin giữ trước.
A32: Bước | B32: Ai làm | C32: Vào đâu (menu) | D32: Việc cần làm | E32: Kết quả / trạng thái / chuyển cho ai
A33: 1 | B33: Kho / Admin | C33: Kho hàng › Quản lý kho | D33: Tạo các kho, đánh dấu Kho runrate; import tồn đầu kỳ (mã SP, mã kho, S/N, ngày nhập). | E33: Kho xuất hiện ở mọi dropdown; tồn đầu đúng. Dòng import sai báo theo số dòng, không nhập.
A34: 2 | B34: Kho | C34: Kho hàng › Nhập kho | D34: Phiếu nhập tự sinh khi PO Team nhận hàng (Chờ xử lý). Đếm hàng, nhập / dán S/N, chọn kho, bấm Duyệt (hoặc Từ chối nếu sai). Nhập khác thì tạo phiếu tay. | E34: Phiếu Hoàn thành, hàng vào tồn đúng kho, gắn Số PO. In phiếu, xuất MISA.
A35: 3 | B35: Sales → Kho / quản lý kho | C35: Kho hàng › Yêu cầu (Ticket) | D35: Sales xin giữ hàng theo model + số lượng ở Kho runrate; Kho duyệt hoặc từ chối kèm lý do. | E35: Số lượng đã giữ không còn trong phần khả dụng; xem được ai đang giữ gì và lịch sử.
A36: 4 | B36: Sales → Admin → Kế toán → Kho | C36: Kho hàng › Xuất kho | D36: Nhận đề xuất từ SO (chuẩn bị hàng). Khi Admin đã duyệt + KT đã xuất HĐ chính thức + đợt "trước xuất hàng" đã thu: chọn kho xuất, quét S/N từng thiết bị, bấm Duyệt, cập nhật ngày giao. | E36: Phiếu Hoàn thành, tồn trừ đúng S/N, S/N gắn khách và bắt đầu bảo hành. In phiếu / biên bản giao, xuất MISA.
A37: 5 | B37: Kho | C37: Kho hàng › Chuyển kho | D37: Chọn kho đi, kho đến, sản phẩm, S/N, số lượng → duyệt. | E37: Kho đi giảm, kho đến tăng đúng S/N.
A38: 6 | B38: Kho → quản lý kho | C38: Kho hàng › Hàng hư hỏng | D38: Báo hỏng / thanh lý: chọn S/N, số lượng, lý do → chờ duyệt → duyệt. | E38: Thiết bị rời tồn khả dụng.
A39: 7 | B39: Kho | C39: Kho hàng › Tồn kho | D39: Xem tồn theo kho / Số PO / S/N, cảnh báo tồn thấp & sắp hết hạn, cột tùy biến, cập nhật S/N hàng loạt, xuất Excel. | E39: Số liệu tồn khớp với các phiếu nhập / xuất / chuyển / hỏng đã duyệt.
A41: KẾ TOÁN – TÀI CHÍNH
A42: Kế toán giữ các "cổng tiền" của đơn hàng: chưa xác nhận đã thu đợt trước đặt hàng thì Mua hàng không chốt được PO; chưa xuất hóa đơn chính thức thì Kho không xuất được hàng. Ngoài ra Kế toán theo dõi công nợ khách hàng và rà soát tổng doanh số theo Hãng.
A43: Bước | B43: Ai làm | C43: Vào đâu (menu) | D43: Việc cần làm | E43: Kết quả / trạng thái / chuyển cho ai
A44: 1 | B44: Kế toán | C44: Hệ thống › Tiền tệ & Tỷ giá; Hệ thống › Cài đặt (mẫu tiến độ thanh toán) | D44: Bật ngoại tệ, nhập / lấy tỷ giá ngày; tạo mẫu chia đợt thanh toán và ngưỡng giá trị đơn bắt buộc thu trước. | E44: Báo giá / đơn USD dùng đúng tỷ giá; Sales áp được mẫu thanh toán.
...

Sheet 1. Sales
A1: CHECKLIST NGHIỆM THU – PHÒNG KINH DOANH (SALES)
A2: Tài khoản test: sales_staff (thao tác chính), sales_manager (duyệt, xem nhóm), director (duyệt P&L, ngoại lệ)
A3: Sales là điểm bắt đầu của mọi đơn hàng: tạo khách hàng, báo giá và đơn hàng bán (SO). Từ SO, hệ thống chuyển việc lần lượt sang Admin, Mua hàng, Kho, Kế toán. Sales không tự đặt hàng hay xuất kho, nhưng phải gửi yêu cầu và theo dõi đến khi khách trả đủ tiền. → Workflow từng bước (ai làm, vào menu nào, kết quả) xem ở sheet "Workflow". Cột "Bước" dưới đây khớp số bước trong Workflow.
A5: Mã TC | B5: Bước | C5: Chức năng | D5: Loại | E5: Tình huống / Thao tác | F5: Kết quả mong đợi | G5: Người test | H5: Ngày test | I5: Kết quả | J5: Kết quả thực tế / Mô tả lỗi (bắt buộc khi Không đạt / Bị chặn) | K5: Mức độ lỗi | L5: Bằng chứng (ảnh, mã chứng từ, tài khoản) | M5: Dev phản hồi | N5: Trạng thái xử lý | O5: Ghi chú
A6: BƯỚC 1: KHÁCH HÀNG & NGƯỜI LIÊN HỆ
A7: SAL-001 | B7: 1 | C7: Khách hàng | D7: Luồng chính | E7: Tạo khách hàng mới đủ thông tin (tên, MST, ngành, địa chỉ) | F7: Lưu thành công, xuất hiện trong danh sách và ô tìm kiếm
A8: SAL-002 | B8: 1 | C8: Khách hàng | D8: Luồng chính | E8: Thêm 2 người liên hệ cho khách | F8: Cả hai hiện trong dropdown P.I.C khi lập báo giá
A9: SAL-003 | B9: 1 | C9: Khách hàng | D9: Phát sinh | E9: Tạo khách có MST trùng với khách đã có | F9: Báo lỗi trùng MST, không tạo bản ghi mới
A10: SAL-004 | B10: 1 | C10: Khách hàng | D10: Phát sinh | E10: Bỏ trống tên hoặc MST rồi lưu | F10: Báo lỗi bắt buộc ngay tại trường
A11: SAL-005 | B11: 1 | C11: Khách hàng | D11: Phát sinh | E11: Thêm liên hệ có email trùng liên hệ khác của cùng khách; thử cùng email ở khách khác | F11: Cùng khách: báo "Email này đã tồn tại…". Khách khác: cho phép
A12: SAL-006 | B12: 1 | C12: Khách hàng | D12: Phát sinh | E12: Nhập email sai định dạng | F12: Báo "Email không đúng định dạng"
A13: SAL-007 | B13: 1 | C13: Khách hàng | D13: Phát sinh | E13: Import khách từ file mẫu có dòng trùng MST và dòng thiếu cột | F13: Báo số dòng thành công / lỗi; dòng lỗi không được tạo
A14: SAL-008 | B14: 1 | C14: Khách hàng | D14: Phát sinh | E14: Sales A mở khách của Sales B (khác nhóm) | F14: Không thấy hoặc không sửa được, đúng phân quyền
A15: SAL-009 | B15: 1 | C15: Khách hàng | D15: Phát sinh | E15: Xóa khách đã có báo giá / đơn hàng | F15: Bị chặn hoặc cảnh báo, không mất dữ liệu liên quan
A16: BƯỚC 2: CƠ HỘI & HOẠT ĐỘNG GẶP KHÁCH
A17: SAL-010 | B17: 2 | C17: Cơ hội | D17: Luồng chính | E17: Tạo cơ hội: chọn khách, loại hoạt động, tiềm năng, mời người tham gia | F17: Người được mời nhận thông báo
A18: SAL-011 | B18: 2 | C18: Cơ hội | D18: Luồng chính | E18: Người được mời bấm Đồng ý | F18: Hoạt động vào Calendar của họ
A19: SAL-012 | B19: 2 | C19: Cơ hội | D19: Luồng chính | E19: Chuyển trạng thái Nháp → Đã lên lịch → Đã xác nhận → Đang thực hiện → Hoàn thành | F19: Mỗi bước đổi trạng thái đúng, có lịch sử
A20: SAL-013 | B20: 2 | C20: Cơ hội | D20: Luồng chính | E20: Chuyển cơ hội thành dự án | F20: Dự án mới mang sẵn khách, nguồn cơ hội
A21: SAL-014 | B21: 2 | C21: Cơ hội | D21: Phát sinh | E21: Hoạt động trình bày giải pháp chưa được BOD/Manager xác nhận, bấm Hoàn thành | F21: Bị chặn, thông báo cần xác nhận
A22: SAL-015 | B22: 2 | C22: Cơ hội | D22: Phát sinh | E22: Yêu cầu quà tặng đang chờ BOD duyệt, bấm Hoàn thành; BOD từ chối quà | F22: Không hoàn thành được; khi bị từ chối Sales nhận thông báo
A23: SAL-016 | B23: 2 | C23: Cơ hội | D23: Phát sinh | E23: Ticket Marketing hoặc Kỹ thuật gắn với cơ hội chưa xong, bấm Hoàn thành | F23: Bị chặn
A24: SAL-017 | B24: 2 | C24: Cơ hội | D24: Phát sinh | E24: Người được mời bấm Từ chối; người không được mời mở link | F24: Từ chối: không xem chi tiết, có nút đổi ý. Không được mời: bị chặn
A25: SAL-018 | B25: 2 | C25: Cơ hội | D25: Phát sinh | E25: Hoãn / hủy hoạt động | F25: Trạng thái đổi, lịch của người tham gia cập nhật
A26: BƯỚC 3: ĐĂNG KÝ DỰ ÁN VỚI HÃNG
A27: SAL-019 | B27: 3 | C27: Đăng ký dự án | D27: Luồng chính | E27: Tạo dự án, chọn Hãng, nhập BOM / file BOM, gửi đăng ký | F27: "Mới đăng ký (Chờ tiếp nhận)", PM/PO Team nhận thông báo
A28: SAL-020 | B28: 3 | C28: Đăng ký dự án | D28: Luồng chính | E28: PM tiếp nhận → gửi Hãng → đính kèm Báo giá Hãng (v1) | F28: Sales nhận "Dự án có Báo giá Hãng mới"
A29: SAL-021 | B29: 3 | C29: Đăng ký dự án | D29: Luồng chính | E29: Hoàn tất ĐKDA, cập nhật tiến độ hàng tháng | F29: "Đã đăng ký – Đang theo đuổi", lưu được cập nhật tháng
A30: SAL-022 | B30: 3 | C30: Đăng ký dự án | D30: Luồng chính | E30: Đóng dự án Closed Won / Closed Lost | F30: Trạng thái đúng, dự án khóa chỉnh sửa
A31: SAL-023 | B31: 3 | C31: Đăng ký dự án | D31: Phát sinh | E31: Gửi đăng ký không có BOM và không có file BOM | F31: Bị chặn "Bắt buộc phải nhập Danh mục BOM…"
A32: SAL-024 | B32: 3 | C32: Đăng ký dự án | D32: Phát sinh | E32: Dự án Fortinet không nhập Net to FTN hoặc nhập 0 | F32: Bị chặn
A33: SAL-025 | B33: 3 | C33: Đăng ký dự án | D33: Phát sinh | E33: Đăng ký trùng dự án đã có | F33: Cảnh báo trùng, hiện Sales đã đăng ký trước
A34: SAL-026 | B34: 3 | C34: Đăng ký dự án | D34: Phát sinh | E34: PM báo trùng → Sales phản hồi "Không trùng"; Sales khác thử phản hồi | F34: Dự án quay lại xử lý; chỉ Sales phụ trách được phản hồi
A35: SAL-027 | B35: 3 | C35: Đăng ký dự án | D35: Phát sinh | E35: PM trả "Thiếu thông tin" → Sales sửa, gửi lại | F35: Log ghi "gửi đăng ký lại (lần 2)"
A36: SAL-028 | B36: 3 | C36: Đăng ký dự án | D36: Phát sinh | E36: PM bấm nhắc Hãng | F36: SLA được gia hạn, có log
A37: SAL-029 | B37: 3 | C37: Đăng ký dự án | D37: Phát sinh | E37: Hãng từ chối → Sales nhân bản dự án | F37: Dự án cũ khóa sửa; bản nhân bản yêu cầu chọn Hãng mới
A38: SAL-030 | B38: 3 | C38: Đăng ký dự án | D38: Phát sinh | E38: Hãng gửi báo giá nhiều lần; xóa 1 phiên bản | F38: Có v1, v2…; xóa 1 bản không ảnh hưởng bản khác
A39: SAL-031 | B39: 3 | C39: Đăng ký dự án | D39: Phát sinh | E39: Thêm P.I.C phụ / người theo dõi | F39: Họ nhận thông báo và thấy dự án
A40: BƯỚC 4: LẬP BÁO GIÁ, GỬI KHÁCH
A41: SAL-032 | B41: 4 | C41: Báo giá | D41: Luồng chính | E41: Tạo báo giá: khách, P.I.C, sản phẩm từ catalog / bảng giá, chiết khấu, VAT | F41: Tổng tiền tính đúng
...

Sheet 2. Mua hàng
A1: CHECKLIST NGHIỆM THU – PHÒNG MUA HÀNG (PO TEAM)
A2: Tài khoản test: purchase_staff (thao tác), purchase_manager (duyệt PO), admin (xóa PO, duyệt yêu cầu đặt hàng)
A3: Mua hàng biến yêu cầu đặt hàng của Sales thành đơn đặt Hãng / NCC (PO), theo dõi hàng trên đường về và xác nhận hàng đã nhận. Một PO có thể gom hàng của nhiều SO cùng Hãng. Khi PO nhận hàng, hệ thống tự tạo phiếu nhập kho cho Kho. → Workflow từng bước (ai làm, vào menu nào, kết quả) xem ở sheet "Workflow". Cột "Bước" dưới đây khớp số bước trong Workflow.
A5: Mã TC | B5: Bước | C5: Chức năng | D5: Loại | E5: Tình huống / Thao tác | F5: Kết quả mong đợi | G5: Người test | H5: Ngày test | I5: Kết quả | J5: Kết quả thực tế / Mô tả lỗi (bắt buộc khi Không đạt / Bị chặn) | K5: Mức độ lỗi | L5: Bằng chứng (ảnh, mã chứng từ, tài khoản) | M5: Dev phản hồi | N5: Trạng thái xử lý | O5: Ghi chú
A6: BƯỚC 1: NHÀ CUNG CẤP & BẢNG GIÁ NCC
A7: PUR-001 | B7: 1 | C7: Nhà cung cấp | D7: Luồng chính | E7: Tạo NCC đủ thông tin; cấu hình mẫu PO riêng | F7: Lưu thành công, mẫu PO áp dụng khi in PO của NCC này
A8: PUR-002 | B8: 1 | C8: Bảng giá NCC | D8: Luồng chính | E8: Import bảng giá Excel (Fortinet / Zyxel / QNAP / SonicWall / Perle) | F8: Tự nhận sheet, cột SKU, cột giá
A9: PUR-003 | B9: 1 | C9: Bảng giá NCC | D9: Luồng chính | E9: Xem trước và áp giá vào sản phẩm; cấu hình chiết khấu | F9: Báo số sản phẩm tạo mới / cập nhật
A10: PUR-004 | B10: 1 | C10: Nhà cung cấp | D10: Phát sinh | E10: Mã NCC trùng; thiếu email / chức vụ người liên hệ | F10: Báo "Mã nhà cung cấp này đã tồn tại" / báo bắt buộc
A11: PUR-005 | B11: 1 | C11: Nhà cung cấp | D11: Phát sinh | E11: Xóa NCC đã có báo giá / đơn đặt hàng / phiếu nhập | F11: Bị chặn, nêu rõ lý do
A12: PUR-006 | B12: 1 | C12: Bảng giá NCC | D12: Phát sinh | E12: File bảng giá trống / chỉ có tiêu đề / không có cột SKU hoặc cột giá | F12: Báo lỗi rõ, không import nửa chừng
A13: PUR-007 | B13: 1 | C13: Bảng giá NCC | D13: Phát sinh | E13: Chiết khấu < 0 hoặc > 100 | F13: Bị chặn
A14: PUR-008 | B14: 1 | C14: Bảng giá NCC | D14: Phát sinh | E14: Tắt bảng giá | F14: Không còn xuất hiện khi tra giá lúc báo giá
A15: BƯỚC 2: TIẾP NHẬN YÊU CẦU ĐẶT HÀNG
A16: PUR-009 | B16: 2 | C16: Tiếp nhận yêu cầu | D16: Luồng chính | E16: Duyệt yêu cầu đặt hàng đủ thông tin | F16: "Đang xử lý", dòng vào Gom đơn cần đặt
A17: PUR-010 | B17: 2 | C17: Tiếp nhận yêu cầu | D17: Phát sinh | E17: Trả yêu cầu thiếu thông tin kèm lý do | F17: "Thiếu thông tin", Sales nhận lý do
A18: PUR-011 | B18: 2 | C18: Tiếp nhận yêu cầu | D18: Phát sinh | E18: Trả đơn về Sales để chỉnh P&L | F18: SO mở lại P&L, ghi nhật ký
A19: PUR-012 | B19: 2 | C19: Tiếp nhận yêu cầu | D19: Phát sinh | E19: Sales sửa thông tin EU tại bước đặt hàng | F19: Bị chặn, chỉ PO Team được sửa
A20: BƯỚC 3: GOM ĐƠN, TẠO PO NHÁP
A21: PUR-013 | B21: 3 | C21: Gom đơn | D21: Luồng chính | E21: Mở Gom đơn cần đặt | F21: Đúng các dòng từ yêu cầu đã duyệt, kèm SO, Sales, số lượng còn cần đặt
A22: PUR-014 | B22: 3 | C22: Gom đơn | D22: Luồng chính | E22: Tạo PO nháp; gộp 2+ PO nháp cùng Hãng | F22: Các dòng về chung 1 PO
A23: PUR-015 | B23: 3 | C23: Gom đơn | D23: Luồng chính | E23: Sinh mã PO tự động, sửa mã thủ công | F23: Kiểm tra trùng mã
A24: PUR-016 | B24: 3 | C24: Gom đơn | D24: Phát sinh | E24: Gộp PO nháp khác Hãng hoặc chỉ chọn 1 PO | F24: Bị chặn
A25: PUR-017 | B25: 3 | C25: Gom đơn | D25: Phát sinh | E25: Đặt số lượng lớn hơn số còn cần đặt | F25: Bị chặn
A26: PUR-018 | B26: 3 | C26: Gom đơn | D26: Phát sinh | E26: Hủy 1 sản phẩm ở bước gom đơn kèm lý do; khôi phục lại | F26: Sales nhận thông báo, P&L mở lại; khôi phục được dòng đã hủy
A27: PUR-019 | B27: 3 | C27: Gom đơn | D27: Phát sinh | E27: Thông báo cho Sales về 1 sản phẩm (hết hàng, đổi model) | F27: Sales nhận thông báo
A28: BƯỚC 4: XÁC NHẬN & DUYỆT PO
A29: PUR-020 | B29: 4 | C29: Duyệt PO | D29: Luồng chính | E29: Xác nhận PO nháp → gửi duyệt → purchase_manager duyệt | F29: "Đã đặt", Sales các SO liên quan nhận thông báo
A30: PUR-021 | B30: 4 | C30: Duyệt PO | D30: Luồng chính | E30: Xem trước / in / xuất Excel PO | F30: Đúng mẫu công ty và mẫu riêng NCC
A31: PUR-022 | B31: 4 | C31: Duyệt PO | D31: Phát sinh | E31: SO có đợt "trước đặt hàng" chưa được KT xác nhận, xác nhận PO nháp | F31: Bị chặn, liệt kê đợt còn thiếu
A32: PUR-023 | B32: 4 | C32: Duyệt PO | D32: Phát sinh | E32: purchase_manager từ chối PO | F32: Người tạo nhận "PO … đã bị từ chối", sửa và gửi duyệt lại
A33: PUR-024 | B33: 4 | C33: Duyệt PO | D33: Phát sinh | E33: Sửa PO không ở trạng thái nháp, hoặc đã hoàn thành / hủy | F33: Bị chặn
A34: PUR-025 | B34: 4 | C34: Duyệt PO | D34: Phát sinh | E34: PO không gắn SO → liên kết thủ công với SO | F34: SO hiển thị tiến độ đặt hàng
A35: BƯỚC 5: GỬI HÃNG, THEO DÕI HÀNG VỀ
A36: PUR-026 | B36: 5 | C36: Gửi Hãng & theo dõi | D36: Luồng chính | E36: Gửi PO qua email cho NCC | F36: Email đến đúng địa chỉ, kèm file PO
A37: PUR-027 | B37: 5 | C37: Gửi Hãng & theo dõi | D37: Luồng chính | E37: NCC xác nhận → cập nhật ETD, ETA, vận đơn | F37: Sales thấy "Hãng đang sản xuất (ETD …)" / "Đang vận chuyển về VN (ETA …)"
A38: PUR-028 | B38: 5 | C38: Gửi Hãng & theo dõi | D38: Luồng chính | E38: Chuyển PO sang "Đang về" | F38: Toàn bộ / từng dòng đổi trạng thái
A39: PUR-029 | B39: 5 | C39: Gửi Hãng & theo dõi | D39: Luồng chính | E39: Upload license cho dòng license | F39: Sales nhận thông báo, xem / tải được
A40: PUR-030 | B40: 5 | C40: Gửi Hãng & theo dõi | D40: Phát sinh | E40: Hold PO kèm lý do; gỡ Hold | F40: Sales nhận thông báo; gỡ Hold thì tiếp tục xử lý
A41: PUR-031 | B41: 5 | C41: Gửi Hãng & theo dõi | D41: Phát sinh | E41: Cập nhật tracking cho PO đã hoàn thành / đã hủy | F41: Bị chặn
...

Sheet 3. Kho
A1: CHECKLIST NGHIỆM THU – KHO
A2: Tài khoản test: warehouse_staff (thao tác), warehouse_manager (duyệt), admin (duyệt đề xuất xuất kho, sửa Số PO phiếu nhập)
A3: Kho giữ số liệu tồn thật: mọi thiết bị theo dõi theo kho, Số PO và S/N. Phiếu nhập sinh từ PO của Mua hàng, phiếu xuất sinh từ đề xuất của Sales. Việc của Kho là kiểm hàng, ghi đúng S/N và bấm duyệt — chỉ khi Kho duyệt thì tồn mới tăng / giảm. Kho runrate là kho hàng có sẵn, Sales được xin giữ trước. → Workflow từng bước (ai làm, vào menu nào, kết quả) xem ở sheet "Workflow". Cột "Bước" dưới đây khớp số bước trong Workflow.
A5: Mã TC | B5: Bước | C5: Chức năng | D5: Loại | E5: Tình huống / Thao tác | F5: Kết quả mong đợi | G5: Người test | H5: Ngày test | I5: Kết quả | J5: Kết quả thực tế / Mô tả lỗi (bắt buộc khi Không đạt / Bị chặn) | K5: Mức độ lỗi | L5: Bằng chứng (ảnh, mã chứng từ, tài khoản) | M5: Dev phản hồi | N5: Trạng thái xử lý | O5: Ghi chú
A6: BƯỚC 1: THIẾT LẬP KHO & TỒN ĐẦU KỲ
A7: WH-001 | B7: 1 | C7: Thiết lập kho | D7: Luồng chính | E7: Tạo kho mới, đánh dấu Kho runrate | F7: Kho xuất hiện ở mọi dropdown chọn kho
A8: WH-002 | B8: 1 | C8: Thiết lập kho | D8: Luồng chính | E8: Import tồn kho từ Excel | F8: Báo số sản phẩm đã nhập, tồn đúng
A9: WH-003 | B9: 1 | C9: Thiết lập kho | D9: Phát sinh | E9: File có dòng thiếu mã kho / mã kho không tồn tại / mã SP không tồn tại / ngày sai / S/N trống hoặc trùng | F9: Báo lỗi theo "Dòng N: …", không nhập dòng lỗi
A10: WH-004 | B10: 1 | C10: Thiết lập kho | D10: Phát sinh | E10: File trống / chỉ có tiêu đề | F10: Báo lỗi
A11: WH-005 | B11: 1 | C11: Thiết lập kho | D11: Phát sinh | E11: Xóa kho đang có hàng | F11: Bị chặn "Không thể xóa kho đang có hàng tồn kho"
A12: BƯỚC 2: NHẬP KHO
A13: WH-006 | B13: 2 | C13: Nhập kho | D13: Luồng chính | E13: PO được nhận hàng → mở phiếu nhập tự sinh | F13: Phiếu "Chờ xử lý" ghi chú tự tạo từ PO; dòng dịch vụ không vào phiếu
A14: WH-007 | B14: 2 | C14: Nhập kho | D14: Luồng chính | E14: Nhập S/N (mỗi dòng 1 S/N hoặc dấu phẩy), duyệt | F14: Hàng vào tồn đúng kho, đúng Số PO
A15: WH-008 | B15: 2 | C15: Nhập kho | D15: Luồng chính | E15: Tạo phiếu nhập tay (hàng mượn, trả lại) → duyệt | F15: Tồn tăng
A16: WH-009 | B16: 2 | C16: Nhập kho | D16: Luồng chính | E16: In phiếu nhập, xuất MISA 1 phiếu / nhiều phiếu | F16: File đúng định dạng
A17: WH-010 | B17: 2 | C17: Nhập kho | D17: Phát sinh | E17: Sản phẩm trên PO chưa có trong danh mục | F17: Tạo nhanh sản phẩm ngay trên phiếu nhập
A18: WH-011 | B18: 2 | C18: Nhập kho | D18: Phát sinh | E18: Nhập S/N đã tồn tại trong hệ thống | F18: Báo "Một hoặc nhiều Serial đã tồn tại…"
A19: WH-012 | B19: 2 | C19: Nhập kho | D19: Phát sinh | E19: Duyệt lại phiếu đã hoàn thành | F19: Báo đã duyệt trước đó, tồn không cộng 2 lần
A20: WH-013 | B20: 2 | C20: Nhập kho | D20: Phát sinh | E20: Từ chối phiếu nhập | F20: Người tạo nhận "Phiếu nhập đã bị từ chối", tồn không đổi
A21: WH-014 | B21: 2 | C21: Nhập kho | D21: Phát sinh | E21: Sửa / xóa phiếu đã hoàn thành; xóa phiếu chờ xử lý / bị từ chối | F21: Hoàn thành: bị chặn. Chờ xử lý / từ chối: xóa được
A22: WH-015 | B22: 2 | C22: Nhập kho | D22: Phát sinh | E22: Sửa Số PO phiếu nhập bằng tài khoản không phải admin; admin sửa | F22: Không phải admin: bị chặn. Admin: tồn gom theo Số PO mới
A23: WH-016 | B23: 2 | C23: Nhập kho | D23: Phát sinh | E23: Nhập kho một phần 2 lần cho cùng PO | F23: 2 phiếu, tổng không vượt số lượng PO
A24: BƯỚC 3: GIỮ HÀNG (KHO RUNRATE)
A25: WH-017 | B25: 3 | C25: Giữ hàng | D25: Luồng chính | E25: Sales tạo yêu cầu giữ hàng theo model, số lượng | F25: Kho nhận "Yêu cầu giữ hàng từ bạn"
A26: WH-018 | B26: 3 | C26: Giữ hàng | D26: Luồng chính | E26: Kho duyệt | F26: Sales nhận thông báo, số giữ không còn trong khả dụng
A27: WH-019 | B27: 3 | C27: Giữ hàng | D27: Luồng chính | E27: Xuất kho đơn có hàng giữ: quét S/N bất kỳ cùng model | F27: Suất giữ chuyển đúng, không bị trừ trùng
A28: WH-020 | B28: 3 | C28: Giữ hàng | D28: Luồng chính | E28: Xem danh sách người đang giữ và lịch sử giữ hàng | F28: Hiển thị đúng
A29: WH-021 | B29: 3 | C29: Giữ hàng | D29: Phát sinh | E29: Giữ số lượng lớn hơn khả dụng | F29: Báo "Không đủ thiết bị khả dụng… (Yêu cầu: x, Khả dụng: y)"
A30: WH-022 | B30: 3 | C30: Giữ hàng | D30: Phát sinh | E30: Chưa cấu hình Kho runrate, tạo / duyệt yêu cầu | F30: Không làm được, thông báo rõ
A31: WH-023 | B31: 3 | C31: Giữ hàng | D31: Phát sinh | E31: Hai Sales cùng giữ 1 model, tổng vượt tồn | F31: Yêu cầu duyệt sau bị chặn
A32: WH-024 | B32: 3 | C32: Giữ hàng | D32: Phát sinh | E32: Từ chối kèm lý do; duyệt yêu cầu không ở trạng thái Chờ duyệt | F32: Sales nhận lý do; duyệt lại: bị chặn
A33: WH-025 | B33: 3 | C33: Giữ hàng | D33: Phát sinh | E33: Item đã bán / hỏng trước khi duyệt | F33: Báo "Item … không còn trong kho"
A34: WH-026 | B34: 3 | C34: Giữ hàng | D34: Phát sinh | E34: Người không có quyền mở lịch sử giữ hàng | F34: Bị chặn
A35: WH-027 | B35: 3 | C35: Giữ hàng | D35: Phát sinh | E35: Mở màn tồn kho sau khi giữ | F35: Tách đúng phần đang giữ, phần khóa CQ, phần khả dụng
A36: BƯỚC 4: XUẤT KHO GIAO KHÁCH
A37: WH-028 | B37: 4 | C37: Xuất kho | D37: Luồng chính | E37: Sales gửi đề xuất xuất kho | F37: Phiếu "Chờ Admin duyệt xuất", Kho nhận thông báo chuẩn bị hàng
A38: WH-029 | B38: 4 | C38: Xuất kho | D38: Luồng chính | E38: Admin duyệt → KT xuất HĐ chính thức | F38: "Chờ KT xuất hóa đơn" → Kho nhận "Đơn hàng sẵn sàng xuất kho"
A39: WH-030 | B39: 4 | C39: Xuất kho | D39: Luồng chính | E39: Chọn kho xuất, quét S/N, duyệt | F39: Phiếu Hoàn thành, tồn trừ đúng S/N, S/N gắn đơn, bắt đầu tính bảo hành
A40: WH-031 | B40: 4 | C40: Xuất kho | D40: Luồng chính | E40: Cập nhật ngày giao hàng | F40: Hạn các đợt "sau giao hàng" tính lại
A41: WH-032 | B41: 4 | C41: Xuất kho | D41: Luồng chính | E41: Xuất một phần | F41: Phần còn lại vẫn còn trên đơn để xuất lần sau
...

Sheet 4. Kế toán
A1: CHECKLIST NGHIỆM THU – KẾ TOÁN – TÀI CHÍNH
A2: Tài khoản test: accountant (thao tác), director / BOD (xóa dòng tổng doanh số, xem báo cáo tài chính)
A3: Kế toán giữ các "cổng tiền" của đơn hàng: chưa xác nhận đã thu đợt trước đặt hàng thì Mua hàng không chốt được PO; chưa xuất hóa đơn chính thức thì Kho không xuất được hàng. Ngoài ra Kế toán theo dõi công nợ khách hàng và rà soát tổng doanh số theo Hãng. → Workflow từng bước (ai làm, vào menu nào, kết quả) xem ở sheet "Workflow". Cột "Bước" dưới đây khớp số bước trong Workflow.
A5: Mã TC | B5: Bước | C5: Chức năng | D5: Loại | E5: Tình huống / Thao tác | F5: Kết quả mong đợi | G5: Người test | H5: Ngày test | I5: Kết quả | J5: Kết quả thực tế / Mô tả lỗi (bắt buộc khi Không đạt / Bị chặn) | K5: Mức độ lỗi | L5: Bằng chứng (ảnh, mã chứng từ, tài khoản) | M5: Dev phản hồi | N5: Trạng thái xử lý | O5: Ghi chú
A6: BƯỚC 1: THIẾT LẬP TÀI CHÍNH
A7: ACC-001 | B7: 1 | C7: Thiết lập | D7: Luồng chính | E7: Bật / tắt tiền tệ; thử tắt VND | F7: Bật tắt được; VND: bị chặn "Không thể tắt tiền tệ cơ sở"
A8: ACC-002 | B8: 1 | C8: Thiết lập | D8: Luồng chính | E8: Nhập tỷ giá tay và lấy tỷ giá hôm nay | F8: Báo giá / đơn mới dùng đúng tỷ giá ngày
A9: ACC-003 | B9: 1 | C9: Thiết lập | D9: Luồng chính | E9: Tạo mẫu tiến độ thanh toán, bật / tắt, đặt ngưỡng | F9: SO vượt ngưỡng bị áp quy tắc thu trước
A10: BƯỚC 2: XÁC NHẬN THANH TOÁN (UNC)
A11: ACC-004 | B11: 2 | C11: Xác nhận UNC | D11: Luồng chính | E11: Sales upload UNC → KT xác nhận | F11: Đợt "Đã thanh toán", giao dịch thu tự sinh, công nợ giảm
A12: ACC-005 | B12: 2 | C12: Xác nhận UNC | D12: Luồng chính | E12: Xác nhận đợt "trước đặt hàng" / "trước xuất hàng" | F12: PO / xuất kho của đơn được mở khóa, Sales nhận thông báo
A13: ACC-006 | B13: 2 | C13: Xác nhận UNC | D13: Luồng chính | E13: KT ghi nhận thanh toán trực tiếp tại đơn | F13: Kết quả như xác nhận UNC
A14: ACC-007 | B14: 2 | C14: Xác nhận UNC | D14: Phát sinh | E14: Xác nhận khi chưa có UNC | F14: Bị chặn "Bắt buộc phải Upload UNC…"
A15: ACC-008 | B15: 2 | C15: Xác nhận UNC | D15: Phát sinh | E15: UNC sai số tiền → Từ chối kèm lý do | F15: Sales nhận thông báo, công nợ không đổi
A16: ACC-009 | B16: 2 | C16: Xác nhận UNC | D16: Phát sinh | E16: Khách trả thiếu / trả gộp nhiều đợt | F16: Phân bổ đúng, đợt còn thiếu vẫn mở
A17: ACC-010 | B17: 2 | C17: Xác nhận UNC | D17: Phát sinh | E17: Tài khoản không phải KT / Admin xác nhận hoặc từ chối | F17: Bị chặn
A18: ACC-011 | B18: 2 | C18: Xác nhận UNC | D18: Phát sinh | E18: Thanh toán ngoại tệ | F18: Chênh lệch tỷ giá được ghi nhận
A19: BƯỚC 3: XUẤT HÓA ĐƠN
A20: ACC-012 | B20: 3 | C20: Xuất hóa đơn | D20: Luồng chính | E20: Yêu cầu cần HĐ nháp: upload nháp → Sales xác nhận → xuất chính thức | F20: "Đã hoàn tất xuất HĐ", Kho nhận thông báo xuất hàng
A21: ACC-013 | B21: 3 | C21: Xuất hóa đơn | D21: Luồng chính | E21: Yêu cầu xuất trực tiếp: đính kèm HĐ | F21: Hoàn tất ngay, không qua Sales duyệt
A22: ACC-014 | B22: 3 | C22: Xuất hóa đơn | D22: Luồng chính | E22: Xuất HĐ theo nhiều đợt đến khi đủ | F22: Báo "Tất cả các sản phẩm … đã được xuất hóa đơn đầy đủ"
A23: ACC-015 | B23: 3 | C23: Xuất hóa đơn | D23: Phát sinh | E23: Sales báo HĐ nháp sai → KT import lại | F23: Lịch sử giữ cả v1, v2
A24: ACC-016 | B24: 3 | C24: Xuất hóa đơn | D24: Phát sinh | E24: Sales xác nhận HĐ không ở trạng thái chờ kiểm tra | F24: Bị chặn
A25: ACC-017 | B25: 3 | C25: Xuất hóa đơn | D25: Phát sinh | E25: Chuyển trạng thái về "Chưa xuất HĐ" | F25: Ghi nhật ký, đơn quay lại bước chờ
A26: ACC-018 | B26: 3 | C26: Xuất hóa đơn | D26: Phát sinh | E26: Hủy yêu cầu đã xử lý | F26: Bị chặn
A27: ACC-019 | B27: 3 | C27: Xuất hóa đơn | D27: Phát sinh | E27: Người không phải KT / Admin upload HĐ | F27: Bị chặn
A28: BƯỚC 4: THEO DÕI CÔNG NỢ KHÁCH HÀNG
A29: ACC-020 | B29: 4 | C29: Công nợ | D29: Luồng chính | E29: Xem công nợ khách | F29: Chỉ gồm đơn đã duyệt / đang giao / hoàn thành; tổng khớp chi tiết
A30: ACC-021 | B30: 4 | C30: Công nợ | D30: Luồng chính | E30: Báo cáo tuổi nợ khách hàng | F30: Chia đúng nhóm ngày quá hạn
A31: ACC-022 | B31: 4 | C31: Công nợ | D31: Luồng chính | E31: Xuất sao kê công nợ khách theo kỳ | F31: Đúng tiêu đề, MST, kỳ, số dư
A32: ACC-023 | B32: 4 | C32: Công nợ | D32: Phát sinh | E32: Nhập số tiền 0, âm, hoặc lớn hơn công nợ còn lại | F32: Bị chặn
A33: ACC-024 | B33: 4 | C33: Công nợ | D33: Phát sinh | E33: Bỏ trống ngày / phương thức thanh toán | F33: Báo bắt buộc
A34: ACC-025 | B34: 4 | C34: Công nợ | D34: Phát sinh | E34: Ghi thu từ màn công nợ cho đơn có tiến độ thanh toán | F34: Hướng dẫn gửi UNC tại chi tiết đơn
A35: ACC-026 | B35: 4 | C35: Công nợ | D35: Phát sinh | E35: Xóa bản ghi thanh toán | F35: Công nợ tăng lại đúng số tiền
A36: BƯỚC 5: TỔNG DOANH SỐ
A37: ACC-027 | B37: 5 | C37: Tổng doanh số | D37: Luồng chính | E37: Đồng bộ dòng mới từ PO; đồng bộ lại lần 2 | F37: Báo số dòng thêm; lần 2 báo "Không có dòng mới"
A38: ACC-028 | B38: 5 | C38: Tổng doanh số | D38: Phát sinh | E38: Sửa ô không cho phép; xóa dòng bằng tài khoản không phải BOD | F38: Bị chặn

Sheet 5. Kỹ thuật
A1: CHECKLIST NGHIỆM THU – PHÒNG KỸ THUẬT
A2: Tài khoản test: technical_engineer (2 tài khoản để test bàn giao), technical_lead, sales_staff (người yêu cầu)
A3: Kỹ thuật làm việc qua ticket. Ai cần kỹ sư (Sales cần BOM, demo, triển khai; khách báo lỗi; nhân viên cần IT) đều tạo ticket. Mỗi ticket có hạn SLA tính bằng giờ làm việc; đồng hồ SLA dừng khi có kỹ sư nhận. Loại đơn giản thì kỹ sư tự nhận, loại phức tạp thì Lead phân công. → Workflow từng bước (ai làm, vào menu nào, kết quả) xem ở sheet "Workflow". Cột "Bước" dưới đây khớp số bước trong Workflow.
A5: Mã TC | B5: Bước | C5: Chức năng | D5: Loại | E5: Tình huống / Thao tác | F5: Kết quả mong đợi | G5: Người test | H5: Ngày test | I5: Kết quả | J5: Kết quả thực tế / Mô tả lỗi (bắt buộc khi Không đạt / Bị chặn) | K5: Mức độ lỗi | L5: Bằng chứng (ảnh, mã chứng từ, tài khoản) | M5: Dev phản hồi | N5: Trạng thái xử lý | O5: Ghi chú
A6: BƯỚC 1: TẠO TICKET & SLA
A7: TEC-001 | B7: 1 | C7: Tạo ticket | D7: Luồng chính | E7: Tạo ticket loại tự nhận (BOM, tài liệu, hậu mãi, IT, khác) | F7: Cả team nhận "sẵn sàng pickup"
A8: TEC-002 | B8: 1 | C8: Tạo ticket | D8: Luồng chính | E8: Tạo ticket loại chỉ Lead (khảo sát, triển khai, đào tạo, sự kiện) | F8: Chỉ Lead nhận "cần phân công"
A9: TEC-003 | B9: 1 | C9: Tạo ticket | D9: Luồng chính | E9: Tạo ticket từ dự án | F9: Lead phụ trách nhận thông báo
A10: TEC-004 | B10: 1 | C10: SLA | D10: Luồng chính | E10: Tạo ticket 16:30 thứ Sáu, ưu tiên Cao | F10: Hạn SLA rơi vào sáng thứ Hai (4 giờ làm việc)
A11: TEC-005 | B11: 1 | C11: SLA | D11: Luồng chính | E11: Thêm ngày lễ trong Cài đặt SLA rồi tạo ticket | F11: Ticket mới bỏ qua ngày lễ khi tính hạn
A12: TEC-006 | B12: 1 | C12: Tạo ticket | D12: Phát sinh | E12: Tạo ticket trùng (cùng khách, cùng nội dung) | F12: Cảnh báo trùng
A13: TEC-007 | B13: 1 | C13: Tạo ticket | D13: Phát sinh | E13: Tài khoản không có quyền tạo ticket | F13: Bị chặn
A14: BƯỚC 2: NHẬN / PHÂN CÔNG / BÀN GIAO
A15: TEC-008 | B15: 2 | C15: Nhận / phân công | D15: Luồng chính | E15: Kỹ sư nhận ticket loại tự nhận | F15: Assigned, SLA dừng
A16: TEC-009 | B16: 2 | C16: Nhận / phân công | D16: Luồng chính | E16: Lead phân công cho kỹ sư | F16: Kỹ sư nhận thông báo
A17: TEC-010 | B17: 2 | C17: Nhận / phân công | D17: Phát sinh | E17: Kỹ sư nhận ticket loại chỉ Lead | F17: Bị chặn theo ma trận phân quyền
A18: TEC-011 | B18: 2 | C18: Nhận / phân công | D18: Phát sinh | E18: Kỹ sư phân công cho người khác | F18: Bị chặn
A19: TEC-012 | B19: 2 | C19: Nhận / phân công | D19: Phát sinh | E19: Phân công cho tài khoản đã khóa / không thuộc team Kỹ thuật | F19: Bị chặn
A20: TEC-013 | B20: 2 | C20: Nhận / phân công | D20: Luồng chính | E20: Bàn giao ticket cho kỹ sư khác | F20: Người mới nhận thông báo, lịch sử giữ người cũ
A21: TEC-014 | B21: 2 | C21: Nhận / phân công | D21: Phát sinh | E21: Người không liên quan bàn giao | F21: Bị chặn
A22: TEC-015 | B22: 2 | C22: Nhận / phân công | D22: Luồng chính | E22: Đổi ma trận quyền ticket kỹ thuật | F22: Quyền nhận thay đổi ngay
A23: BƯỚC 3: XỬ LÝ TICKET
A24: TEC-016 | B24: 3 | C24: Xử lý | D24: Luồng chính | E24: In Progress → Waiting → In Progress → Completed | F24: Lead nhận "Kỹ sư đã hoàn thành… Vui lòng đóng"
A25: TEC-017 | B25: 3 | C25: Xử lý | D25: Luồng chính | E25: Thêm / sửa / xóa nhật ký hỗ trợ | F25: Lưu đúng thời gian, nội dung
A26: TEC-018 | B26: 3 | C26: Xử lý | D26: Phát sinh | E26: Người không phải kỹ sư đang làm / Lead sửa nhật ký | F26: Bị chặn
A27: TEC-019 | B27: 3 | C27: Xử lý | D27: Luồng chính | E27: Trao đổi, upload tài liệu (BOM, slide, hình, cấu hình, biên bản mượn) | F27: Hiển thị trong ticket, tải được
A28: TEC-020 | B28: 3 | C28: Xử lý | D28: Phát sinh | E28: Người chỉ có quyền xem gửi trao đổi / upload | F28: Bị chặn
A29: TEC-021 | B29: 3 | C29: Xử lý | D29: Phát sinh | E29: Upload file không hợp lệ | F29: Báo "Không có tài liệu tải lên nào hợp lệ"
A30: BƯỚC 4: HOÀN THÀNH & ĐÓNG
A31: TEC-022 | B31: 4 | C31: Đóng ticket | D31: Luồng chính | E31: Người yêu cầu gửi yêu cầu đóng; Lead đóng | F31: Closed
A32: TEC-023 | B32: 4 | C32: Đóng ticket | D32: Phát sinh | E32: Người khác gửi yêu cầu đóng; kỹ sư tự đóng | F32: Bị chặn
A33: TEC-024 | B33: 4 | C33: Đóng ticket | D33: Phát sinh | E33: Ticket gắn cơ hội chưa Completed, Sales đóng cơ hội | F33: Cơ hội không hoàn thành được
A34: BƯỚC 5: TRA CỨU S/N
A35: TEC-025 | B35: 5 | C35: Tra cứu S/N | D35: Luồng chính | E35: Tra S/N đã bán | F35: Hiện khách, SO, ngày xuất, hạn bảo hành, license
A36: TEC-026 | B36: 5 | C36: Tra cứu S/N | D36: Phát sinh | E36: Tra S/N không tồn tại | F36: "Không tìm thấy thiết bị"
A37: TEC-027 | B37: 5 | C37: Tra cứu S/N | D37: Phát sinh | E37: Tài khoản không có quyền tra cứu | F37: Bị chặn
A38: BƯỚC 6: BÁO CÁO
A39: TEC-028 | B39: 6 | C39: Báo cáo | D39: Luồng chính | E39: Dashboard kỹ thuật, xuất Excel | F39: Số ticket theo trạng thái, quá SLA, theo kỹ sư khớp danh sách

Sheet 6. Marketing
A1: CHECKLIST NGHIỆM THU – MARKETING
A2: Tài khoản test: marketing, sales_staff (người yêu cầu), director / BOD (duyệt), accountant (thanh toán)
A3: Marketing có 3 mảng: tổ chức sự kiện, phục vụ yêu cầu của Sales (quà tặng, công tác, chi phí), và quản lý kho vật phẩm cùng quỹ hỗ trợ của Hãng. Mọi khoản tốn tiền đều phải qua BOD duyệt, sau đó Kế toán mới chi. → Workflow từng bước (ai làm, vào menu nào, kết quả) xem ở sheet "Workflow". Cột "Bước" dưới đây khớp số bước trong Workflow.
A5: Mã TC | B5: Bước | C5: Chức năng | D5: Loại | E5: Tình huống / Thao tác | F5: Kết quả mong đợi | G5: Người test | H5: Ngày test | I5: Kết quả | J5: Kết quả thực tế / Mô tả lỗi (bắt buộc khi Không đạt / Bị chặn) | K5: Mức độ lỗi | L5: Bằng chứng (ảnh, mã chứng từ, tài khoản) | M5: Dev phản hồi | N5: Trạng thái xử lý | O5: Ghi chú
A6: BƯỚC 1: VẬT PHẨM & QUỸ HÃNG
A7: MKT-001 | B7: 1 | C7: Vật phẩm | D7: Luồng chính | E7: Đề xuất vật phẩm mới → BOD duyệt | F7: Tồn kho vật phẩm được khởi tạo
A8: MKT-002 | B8: 1 | C8: Vật phẩm | D8: Phát sinh | E8: BOD từ chối; người không phải BOD / Admin duyệt | F8: Vật phẩm không dùng được; duyệt: bị chặn
A9: MKT-003 | B9: 1 | C9: Vật phẩm | D9: Luồng chính | E9: Import vật phẩm từ file mẫu | F9: Báo số thêm mới / cập nhật
A10: MKT-004 | B10: 1 | C10: Vật phẩm | D10: Phát sinh | E10: Xuất vật phẩm vượt tồn | F10: Báo "Không đủ tồn kho để xuất. Tồn hiện tại: …"
A11: MKT-005 | B11: 1 | C11: Quỹ Hãng | D11: Luồng chính | E11: Tạo / import quỹ, chi từ quỹ, thu công nợ Hãng | F11: Số dư quỹ giảm khi chi; thu tạo giao dịch tất toán
A12: MKT-006 | B12: 1 | C12: Quỹ Hãng | D12: Phát sinh | E12: Thu lại giao dịch đã tất toán | F12: Bị chặn
A13: BƯỚC 2: SỰ KIỆN
A14: MKT-007 | B14: 2 | C14: Sự kiện | D14: Luồng chính | E14: Tạo sự kiện → gửi duyệt → BOD duyệt / từ chối kèm lý do | F14: Trạng thái đúng, người tạo nhận thông báo
A15: MKT-008 | B15: 2 | C15: Sự kiện | D15: Phát sinh | E15: Sửa sự kiện đang chờ duyệt / đã duyệt | F15: Bị chặn (chỉ sửa khi Nháp / Từ chối)
A16: MKT-009 | B16: 2 | C16: Sự kiện | D16: Phát sinh | E16: Chưa cấu hình quy trình duyệt marketing, gửi duyệt | F16: Báo rõ, không lỗi trang
A17: MKT-010 | B17: 2 | C17: Sự kiện | D17: Luồng chính | E17: Thêm / bỏ khách, cập nhật tham dự từng khách và hàng loạt | F17: Lưu đúng
A18: MKT-011 | B18: 2 | C18: Sự kiện | D18: Luồng chính | E18: Tạo ticket phối hợp cho team khác | F18: Team đó nhận "Sự kiện … cần … phối hợp"
A19: MKT-012 | B19: 2 | C19: Sự kiện | D19: Phát sinh | E19: Thiếu file Excel danh sách khách khi loại yêu cầu bắt buộc | F19: Bị chặn
A20: MKT-013 | B20: 2 | C20: Sự kiện | D20: Phát sinh | E20: Hoàn thành sự kiện chưa duyệt | F20: Bị chặn
A21: MKT-014 | B21: 2 | C21: Sự kiện | D21: Luồng chính | E21: Tạo dự án từ khách của sự kiện | F21: Dự án ghi nguồn "Dự án phát sinh từ sự kiện"
A22: BƯỚC 3: YÊU CẦU MARKETING (QUÀ, CÔNG TÁC, CHI PHÍ)
A23: MKT-015 | B23: 3 | C23: Yêu cầu quà | D23: Luồng chính | E23: Yêu cầu quà từ cơ hội → BOD duyệt → phân công → chấp nhận → phân bổ quà → bàn giao → Hoàn thành | F23: Mỗi bước đúng trạng thái, tồn vật phẩm giảm
A24: MKT-016 | B24: 3 | C24: Yêu cầu quà | D24: Phát sinh | E24: Hoàn tác phân bổ quà; hoàn tác giao dịch không phải xuất quà | F24: Vật phẩm trả về kho; giao dịch khác: bị chặn
A25: MKT-017 | B25: 3 | C25: Yêu cầu quà | D25: Phát sinh | E25: Phân bổ giao dịch thuộc cơ hội / sự kiện khác | F25: Bị chặn
A26: MKT-018 | B26: 3 | C26: Yêu cầu quà | D26: Luồng chính | E26: Nhân sự nộp kết quả → Marketing duyệt / yêu cầu làm lại | F26: Hoàn thành hoặc quay lại thực hiện kèm lý do
A27: MKT-019 | B27: 3 | C27: Yêu cầu quà | D27: Phát sinh | E27: Người không được gán nộp kết quả / cập nhật trạng thái | F27: Bị chặn
A28: MKT-020 | B28: 3 | C28: Công tác | D28: Luồng chính | E28: Gửi yêu cầu đi công tác → BOD duyệt / từ chối | F28: Chỉ BOD thao tác được
A29: MKT-021 | B29: 3 | C29: Chi phí | D29: Luồng chính | E29: Yêu cầu chi phí → BOD duyệt chi → KT xác nhận đã thanh toán | F29: "Chờ thanh toán" → hoàn tất
A30: MKT-022 | B30: 3 | C30: Chi phí | D30: Phát sinh | E30: Người không phải KT xác nhận thanh toán | F30: Bị chặn
A31: MKT-023 | B31: 3 | C31: Yêu cầu | D31: Phát sinh | E31: Để yêu cầu quá hạn | F31: Tự chuyển "Quá hạn"

Sheet 7. BOD - Quản trị
A1: CHECKLIST NGHIỆM THU – BAN GIÁM ĐỐC & QUẢN TRỊ HỆ THỐNG
A2: Tài khoản test: director (BOD), super_admin, admin; thêm 1 tài khoản không có quyền để thử truy cập trái phép
A3: BOD và Admin không có luồng riêng mà đứng ở các điểm duyệt trong luồng của phòng khác. Admin còn cấu hình hệ thống: ai được xem gì, ai duyệt gì, thông tin công ty, sao lưu dữ liệu. BOD dùng dashboard để nắm tình hình kinh doanh. → Workflow từng bước (ai làm, vào menu nào, kết quả) xem ở sheet "Workflow". Cột "Bước" dưới đây khớp số bước trong Workflow.
A5: Mã TC | B5: Bước | C5: Chức năng | D5: Loại | E5: Tình huống / Thao tác | F5: Kết quả mong đợi | G5: Người test | H5: Ngày test | I5: Kết quả | J5: Kết quả thực tế / Mô tả lỗi (bắt buộc khi Không đạt / Bị chặn) | K5: Mức độ lỗi | L5: Bằng chứng (ảnh, mã chứng từ, tài khoản) | M5: Dev phản hồi | N5: Trạng thái xử lý | O5: Ghi chú
A6: BƯỚC 1: PHÂN QUYỀN
A7: ADM-001 | B7: 1 | C7: Phân quyền | D7: Luồng chính | E7: Tạo vai trò, tick quyền trên ma trận | F7: Người có vai trò thấy / mất menu và nút sau khi đăng nhập lại
A8: ADM-002 | B8: 1 | C8: Phân quyền | D8: Luồng chính | E8: Gán quyền trực tiếp cho 1 người, thu hồi | F8: Có hiệu lực đúng
A9: ADM-003 | B9: 1 | C9: Phân quyền | D9: Luồng chính | E9: Kiểm 3 mức xem own / group / all cho báo giá, đơn hàng, PO | F9: Mỗi mức thấy đúng phạm vi
A10: ADM-004 | B10: 1 | C10: Phân quyền | D10: Luồng chính | E10: Nhóm có Lead | F10: Lead thấy dữ liệu thành viên nhóm
A11: ADM-005 | B11: 1 | C11: Phân quyền | D11: Phát sinh | E11: Tài khoản không có quyền gõ thẳng URL trang quản trị / trang duyệt | F11: 403, không lộ dữ liệu
A12: BƯỚC 2: QUY TRÌNH DUYỆT & CÀI ĐẶT
A13: ADM-006 | B13: 2 | C13: Quy trình duyệt | D13: Luồng chính | E13: Tạo / bật / tắt quy trình duyệt nhiều cấp | F13: Chứng từ mới đi đúng các cấp; tắt thì chuyển duyệt thủ công
A14: ADM-007 | B14: 2 | C14: Cài đặt | D14: Luồng chính | E14: Cập nhật thông tin công ty | F14: Hiện trên báo giá, PO, phiếu in
A15: ADM-008 | B15: 2 | C15: Cài đặt | D15: Luồng chính | E15: Cấu hình email, gửi thử | F15: Nhận được mail
A16: ADM-009 | B16: 2 | C16: Cài đặt | D16: Phát sinh | E16: Cấu hình email sai rồi gửi thử | F16: Báo lỗi rõ
A17: BƯỚC 3: HÀNG DUYỆT CỦA BOD / ADMIN
A18: ADM-010 | B18: 3 | C18: Duyệt BOD | D18: Luồng chính | E18: Badge và chuông khi có việc chờ duyệt; duyệt xong | F18: Số đúng, giảm sau khi duyệt
A19: ADM-011 | B19: 3 | C19: Duyệt BOD | D19: Luồng chính | E19: Duyệt / từ chối / yêu cầu sửa P&L; duyệt yêu cầu mở lại P&L | F19: Đúng như mục Sales
A20: ADM-012 | B20: 3 | C20: Duyệt BOD | D20: Luồng chính | E20: Duyệt ngoại lệ thanh toán toàn đơn và từng đợt; ủy quyền rồi thu hồi | F20: Người bị thu hồi không duyệt được nữa
A21: ADM-013 | B21: 3 | C21: Duyệt BOD | D21: Luồng chính | E21: Duyệt hoạt động cơ hội, quà tặng, sự kiện, vật phẩm, chi phí, công tác | F21: Đúng như mục Sales / Marketing
A22: ADM-014 | B22: 3 | C22: Duyệt BOD | D22: Phát sinh | E22: Sửa / xóa đơn đã duyệt P&L bằng tài khoản thiếu quyền edit_/delete_approved_pnl_sales | F22: Bị chặn
A23: BƯỚC 4: DASHBOARD & BÁO CÁO
A24: ADM-015 | B24: 4 | C24: Dashboard | D24: Luồng chính | E24: Dashboard BOD: lọc kỳ / phòng / nhân viên, drill-down | F24: Số liệu khớp danh sách gốc
A25: ADM-016 | B25: 4 | C25: Dashboard | D25: Luồng chính | E25: Dashboard hoạt động kinh doanh: làm mới, xuất file | F25: Chạy được, file đúng
A26: ADM-017 | B26: 4 | C26: Báo cáo | D26: Luồng chính | E26: Báo cáo tổng quan, cơ hội, dự án, bán hàng / margin | F26: Số liệu khớp
A27: ADM-018 | B27: 4 | C27: Báo cáo | D27: Phát sinh | E27: Tài khoản không có quyền export_business_reports xuất báo cáo | F27: Bị chặn
A28: ADM-019 | B28: 4 | C28: Báo cáo | D28: Phát sinh | E28: Chọn kỳ không có dữ liệu | F28: Hiển thị 0 / trống, không lỗi
A29: BƯỚC 5: VẬN HÀNH HỆ THỐNG
A30: ADM-020 | B30: 5 | C30: Dữ liệu | D30: Luồng chính | E30: Sao lưu CSDL, tải file; phục hồi trên môi trường test; lưu trữ dữ liệu cũ | F30: File tải được; phục hồi đúng thời điểm sao lưu
A31: ADM-021 | B31: 5 | C31: Nhật ký | D31: Luồng chính | E31: Mở Nhật ký hoạt động sau các thao tác ở các sheet phòng ban | F31: Ghi đủ ai, lúc nào, thay đổi gì
A32: ADM-022 | B32: 5 | C32: Hướng dẫn | D32: Luồng chính | E32: Admin upload tài liệu hướng dẫn, người dùng tải về | F32: Tải được
A33: BƯỚC 6: NHÂN VIÊN & TÀI KHOẢN
A34: ADM-023 | B34: 6 | C34: Nhân viên | D34: Luồng chính | E34: Tạo nhân viên | F34: Đăng nhập được, thấy đúng menu theo vai trò
A35: ADM-024 | B35: 6 | C35: Nhân viên | D35: Luồng chính | E35: Import nhân viên từ Excel | F35: Báo số thêm / cập nhật / lỗi
A36: ADM-025 | B36: 6 | C36: Nhân viên | D36: Phát sinh | E36: Import file sai định dạng hoặc > 10MB | F36: Bị chặn
A37: ADM-026 | B37: 6 | C37: Nhân viên | D37: Luồng chính | E37: Gán vai trò hàng loạt | F37: Vai trò áp đúng cho người được chọn
A38: ADM-027 | B38: 6 | C38: Nhân viên | D38: Phát sinh | E38: Gán hàng loạt không chọn nhân viên / vai trò | F38: Báo bắt buộc
A39: ADM-028 | B39: 6 | C39: Nhân viên | D39: Luồng chính | E39: Khóa tài khoản; mở khóa | F39: Khóa: không đăng nhập được, không xuất hiện khi phân công. Mở: dùng lại bình thường
A40: ADM-029 | B40: 6 | C40: Nhân viên | D40: Phát sinh | E40: Xóa tài khoản Quản trị viên hệ thống | F40: Bị chặn
A41: ADM-030 | B41: 6 | C41: Nhân viên | D41: Phát sinh | E41: Nhân viên nghỉ đang phụ trách đơn / dự án | F41: Dữ liệu cũ vẫn hiện tên, chuyển giao được

Sheet 8. Liên phòng ban
A1: CHECKLIST NGHIỆM THU – KỊCH BẢN LIÊN PHÒNG BAN (END-TO-END)
A2: Tài khoản test: Mỗi phòng dùng tài khoản của mình, chạy trên cùng 1 đơn hàng thật
A3: Các sheet 1–7 kiểm từng phòng. Sheet này chạy một đơn hàng từ đầu đến cuối để kiểm chỗ bàn giao giữa các phòng: mỗi lần chuyển tay, người nhận phải thấy việc trong danh sách của mình và nhận thông báo. Hai cổng chặn do Kế toán giữ: UNC đợt trước đặt hàng (trước PO) và hóa đơn + UNC trước xuất (trước xuất kho). → Workflow từng bước (ai làm, vào menu nào, kết quả) xem ở sheet "Workflow". Cột "Bước" dưới đây khớp số bước trong Workflow.
A5: Mã TC | B5: Bước | C5: Chức năng | D5: Loại | E5: Tình huống / Thao tác | F5: Kết quả mong đợi | G5: Người test | H5: Ngày test | I5: Kết quả | J5: Kết quả thực tế / Mô tả lỗi (bắt buộc khi Không đạt / Bị chặn) | K5: Mức độ lỗi | L5: Bằng chứng (ảnh, mã chứng từ, tài khoản) | M5: Dev phản hồi | N5: Trạng thái xử lý | O5: Ghi chú
A6: E2E-001 | B6: 1–10 | C6: Kịch bản A – Đơn chuẩn | D6: Luồng chính | E6: Khách mới (thêm nhanh trên báo giá) → báo giá → SO → P&L duyệt → đặt hàng → PO → nhập kho → HĐ → xuất kho → thu đủ | F6: SO "Hoàn thành", công nợ khách = 0, tồn kho về đúng số trước khi nhập
A7: E2E-002 | B7: 1–3, 6–10 | C7: Kịch bản B – Hàng có sẵn Kho runrate | D7: Luồng chính | E7: Giữ hàng → SO → bỏ qua đặt hàng → xuất kho bằng S/N khác cùng model | F7: Suất giữ đúng, tồn khả dụng đúng
A8: E2E-003 | B8: 2–5 | C8: Kịch bản C – Bị trả về giữa chừng | D8: Phát sinh | E8: Admin trả yêu cầu đặt hàng → Sales sửa P&L → duyệt lại → PO Team hủy 1 sản phẩm → P&L mở lại → hoàn tất | F8: Lịch sử SO ghi đủ mọi lần trả về
A9: E2E-004 | B9: 4–5, 10 | C9: Kịch bản D – Khách chưa trả tiền | D9: Phát sinh | E9: Đơn trên ngưỡng có đợt trước đặt hàng → PO bị khóa → BOD duyệt ngoại lệ → PO đi tiếp; đợt sau giao quá hạn | F9: PO mở sau ngoại lệ; đợt quá hạn hiện trong tuổi nợ
A10: E2E-005 | B10: 5–9 | C10: Kịch bản E – Giao từng phần | D10: Phát sinh | E10: PO về 2 đợt, xuất kho 2 lần, xuất HĐ 2 lần | F10: Số lượng, công nợ, tồn kho khớp sau mỗi đợt
A11: E2E-006 | B11: 1–10 | C11: Kịch bản F – Hủy đơn | D11: Phát sinh | E11: Hủy SO trước khi hàng về; thử hủy SO sau khi đã thu tiền | F11: Trước hàng về: PO, phiếu xuất liên quan xử lý đúng. Đã thu tiền: bị chặn
A12: E2E-007 | B12: 9 | C12: Kịch bản G – Sau bán | D12: Luồng chính | E12: Khách báo lỗi → Kỹ thuật tra S/N → mở ticket hậu mãi → đóng | F12: Tra thấy đúng đơn, còn bảo hành; ticket đóng được
A13: E2E-008 | B13: 1–10 | C13: Kiểm tra cuối kịch bản | D13: Luồng chính | E13: Sau mỗi kịch bản đối chiếu: Tồn kho, Công nợ khách hàng, Theo dõi hàng về, Báo cáo bán hàng và Dashboard | F13: Các màn hình khớp nhau và khớp chứng từ đã làm; dashboard cập nhật đúng doanh thu, margin
