Workbook

Sheet Hướng dẫn
A1: CHECKLIST NGHIỆM THU HỆ THỐNG ERP-CRM
A2: Kiểm thử theo workflow của từng phòng ban. Mỗi dòng là một tình huống: thao tác → kết quả mong đợi → người test ghi kết quả thực tế.
A4: 1. Cách làm
A5: Bước 1 | B5: Đọc sheet "Workflow" phần của phòng mình để hiểu thứ tự công việc, ai làm, vào menu nào.
A6: Bước 2 | B6: Mở sheet của phòng mình (Sales, Sales Manager, Legal, BOD, Admin duyệt đơn, …) — xem sheet "Ma trận vai trò" để biết vai trò nào test sheet nào. Làm lần lượt từng dòng, đăng nhập đúng tài khoản ghi ở dòng 2 của sheet.
A7: Bước 3 | B7: Thực hiện cột "Tình huống / Thao tác", so với cột "Kết quả mong đợi", rồi điền các cột nền vàng.
A8: Bước 4 | B8: Khi xong, xem sheet "Tổng hợp" (tự đếm), trưởng phòng ghi kết luận và ký.
A10: 2. Các cột cần điền (nền vàng)
A11: Người test / Ngày test | B11: Tên người thực hiện và ngày test (dd/mm/yyyy).
A12: Kết quả | B12: Chọn trong danh sách: • Đạt – hệ thống chạy đúng như cột Kết quả mong đợi. • Không đạt – chạy khác mong đợi (sai số liệu, không chặn khi phải chặn, lỗi trang, sai thông báo, sai người nhận thông báo…). • Bị chặn – không test được vì bước trước lỗi hoặc thiếu dữ liệu / quyền. • Chưa test – để trống cũng tính là chưa test.
A13: Kết quả thực tế / Mô tả lỗi | B13: BẮT BUỘC khi Không đạt hoặc Bị chặn (ô sẽ tô đỏ nếu bỏ trống). Ghi rõ 3 ý: đã làm gì (dữ liệu nhập) – hệ thống phản hồi gì – sai ở chỗ nào so với mong đợi.
A14: Mức độ lỗi | B14: • Nghiêm trọng – sai tiền, sai tồn kho, mất dữ liệu, không làm tiếp được nghiệp vụ. • Cao – chức năng chính sai nhưng có cách làm tạm. • Trung bình – sai phụ, hiển thị sai, thông báo không rõ. • Thấp – chính tả, giao diện, góp ý.
A15: Bằng chứng | B15: Tên file ảnh chụp màn hình / link, mã chứng từ liên quan (mã báo giá, SO, PO, phiếu…), tài khoản đã dùng.
A16: Dev phản hồi / Trạng thái xử lý | B16: Đội phát triển ghi nguyên nhân, cách sửa và cập nhật trạng thái: Mới → Đang sửa → Đã sửa – chờ test lại → Test lại đạt (hoặc Không sửa kèm lý do). Người test kiểm lại rồi đổi Kết quả.
A17: Ghi chú | B17: Ý kiến khác, đề xuất cải tiến.
A19: 3. Ví dụ một dòng Không đạt (ghi theo mẫu này)
A20: Mã TC | B20: SAL-003
A21: Tình huống / Thao tác | B21: Tạo khách có MST trùng với khách đã có
A22: Kết quả mong đợi | B22: Báo lỗi trùng MST, không tạo bản ghi mới
A23: Kết quả | B23: Không đạt
A24: Kết quả thực tế / Mô tả lỗi | B24: Nhập khách "Công ty ABC 2" với MST 0101234567 (đã có ở "Công ty ABC"). Hệ thống báo "Khách hàng đã được tạo thành công" và danh sách có 2 khách cùng MST. Mong đợi phải chặn và báo trùng MST.
A25: Mức độ lỗi | B25: Cao
A26: Bằng chứng | B26: loi_SAL-003.png; tài khoản sales01
A28: 4. Màu trong file
A29: Nền vàng | B29: Ô người test / dev điền.
A30: Nền xám | B30: Dòng tình huống phát sinh (thiếu dữ liệu, sai dữ liệu, bị từ chối, sai quyền…). Nền trắng là luồng chính.
A31: Dòng xanh nhạt | B31: Tên bước workflow, khớp số bước trong sheet Workflow.
A32: Ô đỏ | B32: Đã chọn Không đạt / Bị chặn nhưng chưa ghi mô tả lỗi hoặc mức độ.
A34: 5. Chuẩn bị trước khi test
A35: Tài khoản | B35: Mỗi vai trò một tài khoản riêng: Sales Staff, Sales Manager, PO Staff, PO Manager, Nhân viên kho, Quản lý kho, Finance Team, Technical Engineer (2), Technical Team Lead, marketing, Legal Team, Order Management, BOD, Admin / Quản trị viên, và 1 tài khoản không có quyền.
A36: Dữ liệu mẫu | B36: 1 khách hàng có sẵn + 1 khách chưa có trong hệ thống; 2 nhà cung cấp; 3 sản phẩm (1 có S/N, 1 không S/N, 1 license); 2 kho (có 1 Kho runrate); 1 bảng giá bán; 1 bảng giá NCC; 1 mẫu tiến độ thanh toán; tỷ giá USD ngày test.
A37: Kiểm ở mọi bước | B37: Thông báo (chuông + email) đến đúng người; badge sidebar tăng / giảm đúng; nhật ký ghi lại người thao tác; người không có quyền không thấy nút và bị chặn khi gọi thẳng URL.

Sheet Tổng hợp
A1: TỔNG HỢP KẾT QUẢ NGHIỆM THU (tự tính từ các sheet phòng ban)
A3: Phòng ban | B3: Sheet | C3: Tổng TC | D3: Đạt | E3: Không đạt | F3: Bị chặn | G3: Chưa test | H3: % đã test | I3: % đạt (trên số đã test) | J3: Lỗi Nghiêm trọng | K3: Lỗi Cao | L3: Trưởng phòng nghiệm thu | M3: Ngày ký | N3: Kết luận | O3: Ghi chú / điều kiện
A4: Kinh doanh (Sales) | B4: 1. Sales | C4: =COUNTIF('1. Sales'!$A$6:$A$600,"SAL-*") | D4: =COUNTIF('1. Sales'!$I$6:$I$600,"Đạt") | E4: =COUNTIF('1. Sales'!$I$6:$I$600,"Không đạt") | F4: =COUNTIF('1. Sales'!$I$6:$I$600,"Bị chặn") | G4: =C4-D4-E4-F4 | H4: =IF(C4=0,0,(D4+E4+F4)/C4) | I4: =IF(D4+E4=0,0,D4/(D4+E4)) | J4: =COUNTIFS('1. Sales'!$I$6:$I$600,"Không đạt",'1. Sales'!$K$6:$K$600,"Nghiêm trọng") | K4: =COUNTIFS('1. Sales'!$I$6:$I$600,"Không đạt",'1. Sales'!$K$6:$K$600,"Cao")
A5: Sales Manager (Trưởng phòng KD) | B5: 2. Sales Manager | C5: =COUNTIF('2. Sales Manager'!$A$6:$A$600,"SM-*") | D5: =COUNTIF('2. Sales Manager'!$I$6:$I$600,"Đạt") | E5: =COUNTIF('2. Sales Manager'!$I$6:$I$600,"Không đạt") | F5: =COUNTIF('2. Sales Manager'!$I$6:$I$600,"Bị chặn") | G5: =C5-D5-E5-F5 | H5: =IF(C5=0,0,(D5+E5+F5)/C5) | I5: =IF(D5+E5=0,0,D5/(D5+E5)) | J5: =COUNTIFS('2. Sales Manager'!$I$6:$I$600,"Không đạt",'2. Sales Manager'!$K$6:$K$600,"Nghiêm trọng") | K5: =COUNTIFS('2. Sales Manager'!$I$6:$I$600,"Không đạt",'2. Sales Manager'!$K$6:$K$600,"Cao")
A6: Legal (Pháp chế) | B6: 3. Legal | C6: =COUNTIF('3. Legal'!$A$6:$A$600,"LEG-*") | D6: =COUNTIF('3. Legal'!$I$6:$I$600,"Đạt") | E6: =COUNTIF('3. Legal'!$I$6:$I$600,"Không đạt") | F6: =COUNTIF('3. Legal'!$I$6:$I$600,"Bị chặn") | G6: =C6-D6-E6-F6 | H6: =IF(C6=0,0,(D6+E6+F6)/C6) | I6: =IF(D6+E6=0,0,D6/(D6+E6)) | J6: =COUNTIFS('3. Legal'!$I$6:$I$600,"Không đạt",'3. Legal'!$K$6:$K$600,"Nghiêm trọng") | K6: =COUNTIFS('3. Legal'!$I$6:$I$600,"Không đạt",'3. Legal'!$K$6:$K$600,"Cao")
A7: BOD | B7: 4. BOD | C7: =COUNTIF('4. BOD'!$A$6:$A$600,"BOD-*") | D7: =COUNTIF('4. BOD'!$I$6:$I$600,"Đạt") | E7: =COUNTIF('4. BOD'!$I$6:$I$600,"Không đạt") | F7: =COUNTIF('4. BOD'!$I$6:$I$600,"Bị chặn") | G7: =C7-D7-E7-F7 | H7: =IF(C7=0,0,(D7+E7+F7)/C7) | I7: =IF(D7+E7=0,0,D7/(D7+E7)) | J7: =COUNTIFS('4. BOD'!$I$6:$I$600,"Không đạt",'4. BOD'!$K$6:$K$600,"Nghiêm trọng") | K7: =COUNTIFS('4. BOD'!$I$6:$I$600,"Không đạt",'4. BOD'!$K$6:$K$600,"Cao")
A8: Admin duyệt đơn (đặt hàng & xuất hàng) | B8: 5. Admin duyệt đơn | C8: =COUNTIF('5. Admin duyệt đơn'!$A$6:$A$600,"OAD-*") | D8: =COUNTIF('5. Admin duyệt đơn'!$I$6:$I$600,"Đạt") | E8: =COUNTIF('5. Admin duyệt đơn'!$I$6:$I$600,"Không đạt") | F8: =COUNTIF('5. Admin duyệt đơn'!$I$6:$I$600,"Bị chặn") | G8: =C8-D8-E8-F8 | H8: =IF(C8=0,0,(D8+E8+F8)/C8) | I8: =IF(D8+E8=0,0,D8/(D8+E8)) | J8: =COUNTIFS('5. Admin duyệt đơn'!$I$6:$I$600,"Không đạt",'5. Admin duyệt đơn'!$K$6:$K$600,"Nghiêm trọng") | K8: =COUNTIFS('5. Admin duyệt đơn'!$I$6:$I$600,"Không đạt",'5. Admin duyệt đơn'!$K$6:$K$600,"Cao")
A9: Order Management (Quản lý đơn hàng) | B9: 6. Order Management | C9: =COUNTIF('6. Order Management'!$A$6:$A$600,"OM-*") | D9: =COUNTIF('6. Order Management'!$I$6:$I$600,"Đạt") | E9: =COUNTIF('6. Order Management'!$I$6:$I$600,"Không đạt") | F9: =COUNTIF('6. Order Management'!$I$6:$I$600,"Bị chặn") | G9: =C9-D9-E9-F9 | H9: =IF(C9=0,0,(D9+E9+F9)/C9) | I9: =IF(D9+E9=0,0,D9/(D9+E9)) | J9: =COUNTIFS('6. Order Management'!$I$6:$I$600,"Không đạt",'6. Order Management'!$K$6:$K$600,"Nghiêm trọng") | K9: =COUNTIFS('6. Order Management'!$I$6:$I$600,"Không đạt",'6. Order Management'!$K$6:$K$600,"Cao")
A10: Mua hàng (PO Team) | B10: 7. Mua hàng | C10: =COUNTIF('7. Mua hàng'!$A$6:$A$600,"PUR-*") | D10: =COUNTIF('7. Mua hàng'!$I$6:$I$600,"Đạt") | E10: =COUNTIF('7. Mua hàng'!$I$6:$I$600,"Không đạt") | F10: =COUNTIF('7. Mua hàng'!$I$6:$I$600,"Bị chặn") | G10: =C10-D10-E10-F10 | H10: =IF(C10=0,0,(D10+E10+F10)/C10) | I10: =IF(D10+E10=0,0,D10/(D10+E10)) | J10: =COUNTIFS('7. Mua hàng'!$I$6:$I$600,"Không đạt",'7. Mua hàng'!$K$6:$K$600,"Nghiêm trọng") | K10: =COUNTIFS('7. Mua hàng'!$I$6:$I$600,"Không đạt",'7. Mua hàng'!$K$6:$K$600,"Cao")
A11: Kho | B11: 8. Kho | C11: =COUNTIF('8. Kho'!$A$6:$A$600,"WH-*") | D11: =COUNTIF('8. Kho'!$I$6:$I$600,"Đạt") | E11: =COUNTIF('8. Kho'!$I$6:$I$600,"Không đạt") | F11: =COUNTIF('8. Kho'!$I$6:$I$600,"Bị chặn") | G11: =C11-D11-E11-F11 | H11: =IF(C11=0,0,(D11+E11+F11)/C11) | I11: =IF(D11+E11=0,0,D11/(D11+E11)) | J11: =COUNTIFS('8. Kho'!$I$6:$I$600,"Không đạt",'8. Kho'!$K$6:$K$600,"Nghiêm trọng") | K11: =COUNTIFS('8. Kho'!$I$6:$I$600,"Không đạt",'8. Kho'!$K$6:$K$600,"Cao")
A12: Kế toán – Tài chính | B12: 9. Kế toán | C12: =COUNTIF('9. Kế toán'!$A$6:$A$600,"ACC-*") | D12: =COUNTIF('9. Kế toán'!$I$6:$I$600,"Đạt") | E12: =COUNTIF('9. Kế toán'!$I$6:$I$600,"Không đạt") | F12: =COUNTIF('9. Kế toán'!$I$6:$I$600,"Bị chặn") | G12: =C12-D12-E12-F12 | H12: =IF(C12=0,0,(D12+E12+F12)/C12) | I12: =IF(D12+E12=0,0,D12/(D12+E12)) | J12: =COUNTIFS('9. Kế toán'!$I$6:$I$600,"Không đạt",'9. Kế toán'!$K$6:$K$600,"Nghiêm trọng") | K12: =COUNTIFS('9. Kế toán'!$I$6:$I$600,"Không đạt",'9. Kế toán'!$K$6:$K$600,"Cao")
A13: Kỹ sư kỹ thuật | B13: 10. Kỹ sư KT | C13: =COUNTIF('10. Kỹ sư KT'!$A$6:$A$600,"TEC-*") | D13: =COUNTIF('10. Kỹ sư KT'!$I$6:$I$600,"Đạt") | E13: =COUNTIF('10. Kỹ sư KT'!$I$6:$I$600,"Không đạt") | F13: =COUNTIF('10. Kỹ sư KT'!$I$6:$I$600,"Bị chặn") | G13: =C13-D13-E13-F13 | H13: =IF(C13=0,0,(D13+E13+F13)/C13) | I13: =IF(D13+E13=0,0,D13/(D13+E13)) | J13: =COUNTIFS('10. Kỹ sư KT'!$I$6:$I$600,"Không đạt",'10. Kỹ sư KT'!$K$6:$K$600,"Nghiêm trọng") | K13: =COUNTIFS('10. Kỹ sư KT'!$I$6:$I$600,"Không đạt",'10. Kỹ sư KT'!$K$6:$K$600,"Cao")
A14: Tech Lead (Trưởng nhóm KT) | B14: 11. Tech Lead | C14: =COUNTIF('11. Tech Lead'!$A$6:$A$600,"TL-*") | D14: =COUNTIF('11. Tech Lead'!$I$6:$I$600,"Đạt") | E14: =COUNTIF('11. Tech Lead'!$I$6:$I$600,"Không đạt") | F14: =COUNTIF('11. Tech Lead'!$I$6:$I$600,"Bị chặn") | G14: =C14-D14-E14-F14 | H14: =IF(C14=0,0,(D14+E14+F14)/C14) | I14: =IF(D14+E14=0,0,D14/(D14+E14)) | J14: =COUNTIFS('11. Tech Lead'!$I$6:$I$600,"Không đạt",'11. Tech Lead'!$K$6:$K$600,"Nghiêm trọng") | K14: =COUNTIFS('11. Tech Lead'!$I$6:$I$600,"Không đạt",'11. Tech Lead'!$K$6:$K$600,"Cao")
A15: Marketing | B15: 12. Marketing | C15: =COUNTIF('12. Marketing'!$A$6:$A$600,"MKT-*") | D15: =COUNTIF('12. Marketing'!$I$6:$I$600,"Đạt") | E15: =COUNTIF('12. Marketing'!$I$6:$I$600,"Không đạt") | F15: =COUNTIF('12. Marketing'!$I$6:$I$600,"Bị chặn") | G15: =C15-D15-E15-F15 | H15: =IF(C15=0,0,(D15+E15+F15)/C15) | I15: =IF(D15+E15=0,0,D15/(D15+E15)) | J15: =COUNTIFS('12. Marketing'!$I$6:$I$600,"Không đạt",'12. Marketing'!$K$6:$K$600,"Nghiêm trọng") | K15: =COUNTIFS('12. Marketing'!$I$6:$I$600,"Không đạt",'12. Marketing'!$K$6:$K$600,"Cao")
A16: Quản trị hệ thống (Admin IT) | B16: 13. Quản trị hệ thống | C16: =COUNTIF('13. Quản trị hệ thống'!$A$6:$A$600,"SYS-*") | D16: =COUNTIF('13. Quản trị hệ thống'!$I$6:$I$600,"Đạt") | E16: =COUNTIF('13. Quản trị hệ thống'!$I$6:$I$600,"Không đạt") | F16: =COUNTIF('13. Quản trị hệ thống'!$I$6:$I$600,"Bị chặn") | G16: =C16-D16-E16-F16 | H16: =IF(C16=0,0,(D16+E16+F16)/C16) | I16: =IF(D16+E16=0,0,D16/(D16+E16)) | J16: =COUNTIFS('13. Quản trị hệ thống'!$I$6:$I$600,"Không đạt",'13. Quản trị hệ thống'!$K$6:$K$600,"Nghiêm trọng") | K16: =COUNTIFS('13. Quản trị hệ thống'!$I$6:$I$600,"Không đạt",'13. Quản trị hệ thống'!$K$6:$K$600,"Cao")
A17: Liên phòng ban (end-to-end) | B17: 14. Liên phòng ban | C17: =COUNTIF('14. Liên phòng ban'!$A$6:$A$600,"E2E-*") | D17: =COUNTIF('14. Liên phòng ban'!$I$6:$I$600,"Đạt") | E17: =COUNTIF('14. Liên phòng ban'!$I$6:$I$600,"Không đạt") | F17: =COUNTIF('14. Liên phòng ban'!$I$6:$I$600,"Bị chặn") | G17: =C17-D17-E17-F17 | H17: =IF(C17=0,0,(D17+E17+F17)/C17) | I17: =IF(D17+E17=0,0,D17/(D17+E17)) | J17: =COUNTIFS('14. Liên phòng ban'!$I$6:$I$600,"Không đạt",'14. Liên phòng ban'!$K$6:$K$600,"Nghiêm trọng") | K17: =COUNTIFS('14. Liên phòng ban'!$I$6:$I$600,"Không đạt",'14. Liên phòng ban'!$K$6:$K$600,"Cao")
A18: TỔNG CỘNG | C18: =SUM(C4:C17) | D18: =SUM(D4:D17) | E18: =SUM(E4:E17) | F18: =SUM(F4:F17) | G18: =SUM(G4:G17) | H18: =IF(C18=0,0,(D18+E18+F18)/C18) | I18: =IF(D18+E18=0,0,D18/(D18+E18)) | J18: =SUM(J4:J17) | K18: =SUM(K4:K17)
A20: Quy ước kết luận:
A21: • Đạt: mọi dòng đã test, không còn lỗi Nghiêm trọng / Cao chưa sửa.
A22: • Đạt có điều kiện: còn lỗi Trung bình / Thấp — ghi danh sách mã TC và hạn sửa vào cột Ghi chú.
A23: • Không đạt: còn lỗi Nghiêm trọng / Cao, hoặc còn dòng Bị chặn / Chưa test ở luồng chính.

Sheet Ma trận vai trò
A1: MA TRẬN VAI TRÒ – ai làm gì, ai duyệt gì, test ở sheet nào
A2: Điền cột "Người thực hiện" bằng tên người thật đang giữ vai trò đó. Quyền duyệt ghi theo code hiện tại; nếu thực tế công ty phân công khác thì ghi chú để chỉnh phân quyền.
A4: Vai trò (tên trên hệ thống) | B4: Chức danh | C4: Người thực hiện (điền tên) | D4: Làm gì trong hệ thống | E4: Duyệt gì | F4: Sheet test
A5: Sales Staff | B5: Nhân viên kinh doanh | D5: Khách hàng, cơ hội, ĐKDA, báo giá, đơn hàng, P&L, yêu cầu đặt hàng, yêu cầu xuất HĐ / xuất kho, upload UNC | E5: — | F5: 1. Sales
A6: Sales Manager | B6: Trưởng phòng kinh doanh | D6: Xem dữ liệu cả nhóm, xác nhận hoạt động, P.I.C phụ, gửi P&L thay Sales, đôn đốc công nợ | E6: Yêu cầu đặt hàng (code cho phép) | F6: 2. Sales Manager
A7: Legal Team | B7: Pháp chế | D7: Thẩm định hợp đồng & P&L | E7: P&L / HĐMB cấp 1 | F7: 3. Legal
A8: BOD | B8: Ban giám đốc | D8: Dashboard, báo cáo | E8: P&L cấp 2, ngoại lệ thanh toán, mở lại P&L, quà tặng, ngân sách MKT cấp 2, vật phẩm, chi phí, công tác | F8: 4. BOD
A9: Admin | B9: Admin kiểm soát đơn hàng | D9: Kiểm tra hồ sơ ở khâu đặt hàng và khâu xuất hàng; sửa Số PO phiếu nhập; xóa PO | E9: Yêu cầu đặt hàng, đề xuất xuất kho | F9: 5. Admin duyệt đơn
A10: Order Management | B10: Quản lý đơn hàng (chị Bích) | D10: Kiểm soát đơn hàng từ lúc đặt hàng đến xuất hàng; quản lý PO Team (PR, gom đơn, PO, NCC, bảng giá NCC, báo cáo mua hàng); xem toàn bộ báo giá, đơn hàng | E10: Yêu cầu đặt hàng, tiếp nhận PR, PO, đề xuất xuất kho, ngân sách Marketing cấp 1 | F10: 6. Order Management
A11: PO Staff | B11: Nhân viên mua hàng (PO Team) | D11: Bảng giá NCC, gom đơn, PO, theo dõi hàng về, nhận hàng, S/N | E11: — | F11: 7. Mua hàng
A12: PO Manager | B12: Trưởng phòng mua hàng | D12: Như PO Staff | E12: PO; theo code cũng duyệt được yêu cầu đặt hàng và xuất kho | F12: 7. Mua hàng
A13: Nhân viên kho | B13: Nhân viên kho | D13: Nhập kho, xuất kho, chuyển kho, giữ hàng, hàng hỏng, tồn kho | E13: — | F13: 8. Kho
A14: Quản lý kho | B14: Quản lý kho | D14: Như Nhân viên kho | E14: Phiếu nhập / xuất / chuyển, yêu cầu giữ hàng, báo hỏng | F14: 8. Kho
A15: Finance Team | B15: Kế toán | D15: Tỷ giá, mẫu thanh toán, công nợ khách hàng, tổng doanh số | E15: Xác nhận UNC, xuất hóa đơn, chi phí Marketing | F15: 9. Kế toán
A16: Technical Engineer | B16: Kỹ sư kỹ thuật | D16: Nhận và xử lý ticket, nhật ký hỗ trợ, tra cứu S/N | E16: — | F16: 10. Kỹ sư KT
... A19: Quản trị viên / Admin | B19: Quản trị hệ thống | D19: Nhân viên, tài khoản, vai trò, quyền, quy trình duyệt, cài đặt, sao lưu | E19: — | F19: 13. Quản trị hệ thống

Sheet Workflow
A1: WORKFLOW CHI TIẾT TỪNG PHÒNG BAN – đọc trước khi test
A3: PHÒNG KINH DOANH (SALES)
A4: Sales là điểm bắt đầu của mọi đơn hàng: tạo khách hàng, báo giá và đơn hàng bán (SO). Từ SO, hệ thống chuyển việc lần lượt sang Admin, Mua hàng, Kho, Kế toán. Sales không tự đặt hàng hay xuất kho, nhưng phải gửi yêu cầu và theo dõi đến khi khách trả đủ tiền.
A5: Bước | B5: Ai làm | C5: Vào đâu (menu) | D5: Việc cần làm | E5: Kết quả / trạng thái / chuyển cho ai
A6: 1 | B6: Sales | C6: Master Data › Khách hàng | D6: Tạo khách hàng (tên, MST không trùng, ngành, địa chỉ) và ít nhất 1 người liên hệ (P.I.C) có tên, SĐT, email. | E6: Khách xuất hiện trong ô tìm khách ở Cơ hội, Đăng ký dự án, Báo giá. Đang lập báo giá mà chưa có khách thì dùng nút "Thêm khách hàng nhanh" trên form báo giá.
A7: 2 | B7: Sales, người được mời, BOD/Manager, Marketing | C7: Bán hàng › Cơ hội | D7: Ghi nhận hoạt động gặp khách (gặp, demo, trình bày giải pháp...), mức tiềm năng 25–90%, mời người tham gia; khai quà tặng nếu cần, tạo ticket Kỹ thuật nếu cần kỹ sư đi cùng. | E7: Nháp → Đã lên lịch → Đã xác nhận → Đang thực hiện → Đã hoàn thành (hoặc Hoãn / Hủy). Chỉ hoàn thành được khi BOD đã xác nhận và ticket MKT/Kỹ thuật đi kèm đã xong. Cơ hội chín muồi → chuyển thành dự án.
A8: 3 | B8: Sales → PM/PO Team | C8: Bán hàng › Đăng ký dự án | D8: Đăng ký dự án với Hãng: khách, Hãng, BOM hoặc file BOM (bắt buộc), giá trị dự kiến; dự án Fortinet nhập thêm Net to FTN. | E8: Mới đăng ký → Đang xử lý tiếp nhận → Đã gửi Hãng → Hãng đã báo giá/duyệt → Đã đăng ký – Đang theo đuổi → Closed Won / Lost. Nhánh: Thiếu thông tin, Dự án trùng, Hãng từ chối.
A9: 4 | B9: Sales | C9: Bán hàng › Báo giá › Tạo mới | D9: Nhập khách + P.I.C, dự án (nếu có, tải nhanh BOM), tiêu đề, ngày & hạn báo giá, sản phẩm, số lượng, đơn giá, chiết khấu, VAT, tiền tệ, điều khoản. Gửi khách bằng PDF / Excel / email. | E9: Nháp → Đã gửi khách → KH chốt giá (hoặc Khách từ chối). Quá hạn chưa chốt → Hết hạn, muốn báo lại thì Nhân bản.
A10: 5 | B10: Sales | C10: Báo giá › Chuyển đơn hàng | D10: Trên báo giá đã chốt, bấm Chuyển đơn hàng. | E10: Sinh SO mã SO-YYYYMMDD-xxxx mang theo khách, sản phẩm, giá. Có dự án → "Bán theo dự án", không → "Bán lẻ". Báo giá bị khóa.
A11: 6 | B11: Sales → Legal (cấp 1) → BOD (cấp 2) | C11: Bán hàng › Đơn hàng bán › mở SO | D11: Lập P&L (giá vốn, chi phí, margin), tiến độ thanh toán (đợt trước đặt hàng / trước xuất hàng / sau giao hàng), P.I.C phụ; bấm Gửi duyệt P&L. | E11: P&L: Nháp → Chờ duyệt (Legal cấp 1 → BOD cấp 2) → Đã duyệt (hoặc Yêu cầu chỉnh sửa / Từ chối ở cấp nào cũng được). Sau khi gửi, SO bị khóa; muốn sửa đơn đã duyệt phải xin mở lại P&L.
A12: 7 | B12: Sales → Admin → PO Team | C12: SO › Tạo yêu cầu đặt hàng (danh sách: Bán hàng › Yêu cầu đặt hàng) | D12: Nhập Hãng, loại đơn, dòng cần đặt, POS-ID, End User (nếu cần CQ), S/N (Trade-up), file đính kèm bắt buộc. Hàng có sẵn ở Kho runrate thì tạo yêu cầu giữ hàng thay vì đặt. | E12: Bản nháp → Chờ Admin duyệt (Admin kiểm hồ sơ) → Đã gửi → Đang xử lý → Hoàn thành. Có thể bị trả về "Thiếu thông tin" hoặc trả về sửa P&L.
A13: 8 | B13: Sales | C13: Bán hàng › Theo dõi hàng về | D13: Theo dõi tiến độ đặt hàng và hàng về; tải license nếu có. | E13: Chờ đặt hàng → Đã đặt hàng → Chờ hàng về (ETD, ETA) → Hàng đã về. PO bị Hold thì Sales nhận thông báo kèm lý do.
A14: 9 | B14: Sales → Admin → Kế toán → Kho | C14: SO | D14: Tạo yêu cầu xuất hóa đơn (chọn cần HĐ nháp hay xuất trực tiếp); gửi đề xuất xuất kho (được xuất một phần); cập nhật ngày giao hàng. | E14: Phiếu xuất: Chờ Admin duyệt xuất → Chờ KT xuất HĐ → Kho xuất thực tế. Ngày giao là mốc tính hạn các đợt "sau giao hàng".
A15: 10 | B15: Sales → Kế toán (BOD nếu ngoại lệ) | C15: SO › Tiến độ thanh toán | D15: Upload UNC cho từng đợt khi khách chuyển khoản; xin duyệt ngoại lệ nếu khách muốn đặt/xuất trước khi trả. | E15: Kế toán xác nhận → đợt Đã thanh toán, công nợ giảm, bước bị khóa được mở. Giao đủ + HĐ đủ + thu đủ → SO Hoàn thành.
A16: 11 | B16: Mọi nhân viên | C16: Bán hàng › Đặt phòng họp | D16: Chọn phòng, ngày, giờ, tiêu đề, người tham dự. | E16: Người được mời nhận lời mời và phản hồi; hệ thống chặn đặt trùng giờ.
A17: 12 | B17: Sales / Sales Manager | C17: Bán hàng › Báo cáo tần suất gặp, Báo cáo bán hàng, Công nợ khách hàng | D17: Xem số lần gặp khách theo Sales, doanh thu / margin theo kỳ, công nợ khách của mình. | E17: Số liệu khớp cơ hội và đơn hàng thực tế.
A19: SALES MANAGER (TRƯỞNG PHÒNG KINH DOANH)
A20: Sales Manager quản lý một nhóm Sales: xem toàn bộ dữ liệu của nhóm, xác nhận hoạt động gặp khách, phân P.I.C phụ và tỷ lệ chia margin, rà P&L và gửi duyệt thay Sales, đôn đốc công nợ. Sales Manager KHÔNG duyệt P&L — P&L do Legal (cấp 1) rồi BOD (cấp 2) duyệt. Theo code, Sales Manager cũng được duyệt yêu cầu đặt hàng như Admin.
A21: Bước | B21: Ai làm | C21: Vào đâu (menu) | D21: Việc cần làm | E21: Kết quả / trạng thái / chuyển cho ai
A22: 1 | B22: Sales Manager | C22: Master Data › Khách hàng; Bán hàng › Cơ hội, Báo giá, Đơn hàng bán | D22: Mở các danh sách để theo dõi công việc của nhóm. | E22: Thấy dữ liệu của mình và thành viên nhóm; không thấy nhóm khác.
A23: 2 | B23: Sales → Sales Manager | C23: Bán hàng › Cơ hội | D23: Xác nhận hoạt động gặp khách (chuyển sang "Đã xác nhận"); khi xác nhận có thể chọn kỹ sư đi cùng, duyệt / từ chối quà và xuất vật phẩm MKT. | E23: Mọi hoạt động phải được xác nhận mới Hoàn thành được; hoạt động trình bày giải pháp / cần kỹ sư / có quà còn phải xác nhận trước khi chuyển Đang thực hiện.
A24: 3 | B24: Sales Manager | C24: Bán hàng › Đăng ký dự án; Đơn hàng bán | D24: Chỉ định P.I.C phụ cho dự án (Sales Manager cùng phòng ban với Sales phụ trách dự án) và cho đơn hàng (chọn cách chia margin: người chính 100% / người phụ 100% / chia theo %). | E24: P.I.C phụ nhận thông báo; margin đơn hàng chia đúng cách đã chọn.
A25: 4 | B25: Sales Manager → Legal → BOD | C25: Đơn hàng bán › P&L | D25: Rà giá vốn, chi phí, margin, tiến độ thanh toán của đơn trong nhóm; gửi duyệt thay Sales khi cần; theo dõi đơn đang chờ cấp nào. | E25: P&L sang "Chờ duyệt" cấp 1 (Legal).
A26: 5 | B26: Sales → Sales Manager → PO Team | C26: SO › Yêu cầu đặt hàng ("Chờ Admin duyệt") | D26: Nếu công ty giao Sales Manager duyệt: kiểm tra hồ sơ như Admin (xem sheet Admin duyệt đơn) rồi duyệt hoặc trả về. | E26: Duyệt → "Đã gửi" sang PO Team; trả về → Sales nhận lý do.
A27: 6 | B27: Sales Manager | C27: SO › Tiến độ thanh toán; Bán hàng › Công nợ khách hàng | D27: Upload UNC thay Sales; lọc nợ quá hạn của nhóm, giao Sales bám khách; xin ngoại lệ thanh toán khi cần. | E27: Kế toán nhận UNC; công nợ nhóm hiển thị đúng.
A28: 7 | B28: Sales Manager | C28: Bán hàng › Báo cáo tần suất gặp, Báo cáo bán hàng; Dashboard | D28: Theo dõi số lần gặp khách, doanh thu, margin của từng người trong nhóm. | E28: Số liệu khớp dữ liệu thực tế của nhóm.
A30: LEGAL TEAM (PHÁP CHẾ) – DUYỆT CẤP 1 HỢP ĐỒNG & P&L
A31: Legal là cấp duyệt 1 của mọi đơn hàng bán, trước BOD. Legal kiểm tra hợp đồng mua bán (HĐMB) và bảng P&L, rồi duyệt, yêu cầu Sales chỉnh sửa, hoặc từ chối. Legal không sửa đơn. Quy trình cấu hình ở Hệ thống › Quy trình duyệt: "Quy trình duyệt P&L & Hợp đồng bán hàng" – Cấp 1 Legal Team → Cấp 2 BOD.
A32: Bước | B32: Ai làm | C32: Vào đâu (menu) | D32: Việc cần làm | E32: Kết quả / trạng thái / chuyển cho ai
A33: 1 | B33: Sales → Legal | C33: Chuông thông báo; Bán hàng › Đơn hàng bán (lọc Chờ duyệt) | D33: Nhận đơn Sales vừa gửi duyệt P&L. | E33: Đơn ở cấp 1 – Legal.
A34: 2 | B34: Legal | C34: SO › thông tin đơn, file đính kèm, tab P&L | D34: Kiểm tra: pháp nhân khách (tên, MST, địa chỉ); số HĐMB; điều khoản thanh toán khớp tiến độ thanh toán trên SO; phạt vi phạm, bảo hành; file hợp đồng / PO của khách đã đính kèm; P&L (giá vốn, chi phí, chiết khấu, margin) hợp lý. | E34: Đủ cơ sở để quyết định.
A35: 3 | B35: Legal → BOD / Sales | C35: SO › Duyệt / Yêu cầu chỉnh sửa / Từ chối (kèm ghi chú) | D35: Ra quyết định cấp 1. | E35: Duyệt → chuyển BOD duyệt cấp 2. Yêu cầu chỉnh sửa → P&L mở lại cho Sales. Từ chối → P&L Từ chối.
A36: 4 | B36: Legal | C36: SO › Lịch sử duyệt | D36: Theo dõi đơn đã duyệt; đơn Sales sửa xong gửi lại sẽ quay về cấp 1. | E36: Lịch sử ghi đủ các lần duyệt.
A38: BAN GIÁM ĐỐC (DIRECTOR)
A39: BOD là cấp duyệt cuối: duyệt P&L cấp 2 sau Legal, quyết định ngoại lệ thanh toán (cho đặt hàng / xuất hàng khi khách chưa trả), mở lại P&L đã duyệt, duyệt các khoản chi Marketing. BOD theo dõi kinh doanh qua Dashboard.
A40: Bước | B40: Ai làm | C40: Vào đâu (menu) | D40: Việc cần làm | E40: Kết quả / trạng thái / chuyển cho ai
A41: 1 | B41: Legal → BOD | C41: Chuông thông báo; SO | D41: Xem đơn Legal đã duyệt cấp 1, duyệt / yêu cầu sửa / từ chối. | E41: Duyệt → P&L Đã duyệt, mở khóa tạo yêu cầu đặt hàng.
A42: 2 | B42: Sales → BOD | C42: SO › Tiến độ thanh toán | D42: Duyệt ngoại lệ toàn đơn hoặc từng đợt; hoặc ủy quyền cho người khác duyệt, thu hồi ủy quyền. | E42: Bước bị khóa (đặt hàng / xuất hàng) được mở.
A43: 3 | B43: Sales → BOD | C43: SO › Yêu cầu mở lại P&L | D43: Duyệt hoặc từ chối yêu cầu mở lại P&L đã duyệt. | E43: Duyệt → P&L mở cho Sales sửa.
A44: 4 | B44: Sales / Marketing / OM → BOD | C44: Bán hàng › Cơ hội, Sự kiện Marketing, Kho vật phẩm MKT | D44: Xác nhận hoạt động, duyệt quà tặng; duyệt ngân sách sự kiện cấp 2 (sau Order Management cấp 1); duyệt vật phẩm mới, chi phí, công tác. | E44: Marketing / Kế toán được làm bước tiếp theo.
...

Sheet 1. Sales
A1: CHECKLIST NGHIỆM THU – PHÒNG KINH DOANH (SALES)
A2: Tài khoản test: Sales Staff (thao tác chính), Sales Manager (duyệt, xem nhóm), BOD (duyệt P&L, ngoại lệ)
A3: Sales là điểm bắt đầu của mọi đơn hàng: tạo khách hàng, báo giá và đơn hàng bán (SO). Từ SO, hệ thống chuyển việc lần lượt sang Admin, Mua hàng, Kho, Kế toán. Sales không tự đặt hàng hay xuất kho, nhưng phải gửi yêu cầu và theo dõi đến khi khách trả đủ tiền. → Workflow từng bước (ai làm, vào menu nào, kết quả) xem ở sheet "Workflow". Cột "Bước" dưới đây khớp số bước trong Workflow.
A5: Mã TC | B5: Bước | C5: Chức năng | D5: Loại | E5: Tình huống / Thao tác | F5: Kết quả mong đợi | G5: Người test | H5: Ngày test | I5: Kết quả | J5: Kết quả thực tế / Mô tả lỗi (bắt buộc khi Không đạt / Bị chặn) | K5: Mức độ lỗi | L5: Bằng chứng (ảnh, mã chứng từ, tài khoản) | M5: Dev phản hồi | N5: Trạng thái xử lý | O5: Ghi chú
A6: BƯỚC 1: KHÁCH HÀNG & NGƯỜI LIÊN HỆ
A7: SAL-001 | B7: 1 | C7: Khách hàng | D7: Luồng chính | E7: Tạo khách hàng mới đủ thông tin (tên, MST, ngành, địa chỉ) | F7: Lưu thành công, xuất hiện trong danh sách và ô tìm kiếm
A8: SAL-002 | B8: 1 | C8: Khách hàng | D8: Luồng chính | E8: Thêm 2 người liên hệ cho khách | F8: Cả hai hiện trong dropdown P.I.C khi lập báo giá
A9: SAL-003 | B9: 1 | C9: Khách hàng | D9: Phát sinh | E9: Tạo khách có MST trùng với khách đã có | F9: Báo lỗi trùng MST, không tạo bản ghi mới
A10: SAL-004 | B10: 1 | C10: Khách hàng | D10: Phát sinh | E10: Bỏ trống tên hoặc MST rồi lưu | F10: Báo lỗi bắt buộc ngay tại trường
A11: SAL-005 | B11: 1 | C11: Khách hàng | D11: Phát sinh | E11: Thêm liên hệ có email trùng liên hệ khác của cùng khách; thử cùng email ở khách khác | F11: Cùng khách: báo "Email này đã tồn tại…". Khách khác: cho phép
A12: SAL-006 | B12: 1 | C12: Khách hàng | D12: Phát sinh | E12: Nhập email sai định dạng | F12: Báo "Email không đúng định dạng"
A13: SAL-007 | B13: 1 | C13: Khách hàng | D13: Phát sinh | E13: Import khách từ file mẫu có dòng trùng MST và dòng thiếu cột | F13: Báo số dòng thành công / lỗi; dòng lỗi không được tạo
A14: SAL-008 | B14: 1 | C14: Khách hàng | D14: Phát sinh | E14: Sales A mở khách của Sales B (khác nhóm) | F14: Không thấy hoặc không sửa được, đúng phân quyền
A15: SAL-009 | B15: 1 | C15: Khách hàng | D15: Phát sinh | E15: Xóa khách đã có báo giá / đơn hàng | F15: Bị chặn hoặc cảnh báo, không mất dữ liệu liên quan
A16: BƯỚC 2: CƠ HỘI & HOẠT ĐỘNG GẶP KHÁCH
A17: SAL-010 | B17: 2 | C17: Cơ hội | D17: Luồng chính | E17: Tạo cơ hội: chọn khách, loại hoạt động, tiềm năng, mời người tham gia | F17: Người được mời nhận thông báo
A18: SAL-011 | B18: 2 | C18: Cơ hội | D18: Luồng chính | E18: Người được mời bấm Đồng ý | F18: Hoạt động vào Calendar của họ
A19: SAL-012 | B19: 2 | C19: Cơ hội | D19: Luồng chính | E19: Chuyển trạng thái Nháp → Đã lên lịch → Đã xác nhận → Đang thực hiện → Hoàn thành | F19: Mỗi bước đổi trạng thái đúng, có lịch sử
A20: SAL-013 | B20: 2 | C20: Cơ hội | D20: Luồng chính | E20: Chuyển cơ hội thành dự án | F20: Dự án mới mang sẵn khách, nguồn cơ hội
A21: SAL-014 | B21: 2 | C21: Cơ hội | D21: Phát sinh | E21: Hoạt động trình bày giải pháp chưa được BOD/Manager xác nhận, bấm Hoàn thành | F21: Bị chặn, thông báo cần xác nhận
A22: SAL-015 | B22: 2 | C22: Cơ hội | D22: Phát sinh | E22: Yêu cầu quà tặng đang chờ BOD duyệt, bấm Hoàn thành; BOD từ chối quà | F22: Không hoàn thành được; khi bị từ chối Sales nhận thông báo
A23: SAL-016 | B23: 2 | C23: Cơ hội | D23: Phát sinh | E23: Ticket Marketing hoặc Kỹ thuật gắn với cơ hội chưa xong, bấm Hoàn thành | F23: Bị chặn
A24: SAL-017 | B24: 2 | C24: Cơ hội | D24: Phát sinh | E24: Người được mời bấm Từ chối; người không được mời mở link | F24: Từ chối: không xem chi tiết, có nút đổi ý. Không được mời: bị chặn
A25: SAL-018 | B25: 2 | C25: Cơ hội | D25: Phát sinh | E25: Hoãn / hủy hoạt động | F25: Trạng thái đổi, lịch của người tham gia cập nhật
A26: BƯỚC 3: ĐĂNG KÝ DỰ ÁN VỚI HÃNG
A27: SAL-019 | B27: 3 | C27: Đăng ký dự án | D27: Luồng chính | E27: Tạo dự án, chọn Hãng, nhập BOM / file BOM, gửi đăng ký | F27: "Mới đăng ký (Chờ tiếp nhận)", PM/PO Team nhận thông báo
A28: SAL-020 | B28: 3 | C28: Đăng ký dự án | D28: Luồng chính | E28: PM tiếp nhận → gửi Hãng → đính kèm Báo giá Hãng (v1) | F28: Sales nhận "Dự án có Báo giá Hãng mới"
A29: SAL-021 | B29: 3 | C29: Đăng ký dự án | D29: Luồng chính | E29: Hoàn tất ĐKDA, cập nhật tiến độ hàng tháng | F29: "Đã đăng ký – Đang theo đuổi", lưu được cập nhật tháng
A30: SAL-022 | B30: 3 | C30: Đăng ký dự án | D30: Luồng chính | E30: Đóng dự án Closed Won / Closed Lost | F30: Trạng thái đúng, dự án khóa chỉnh sửa
A31: SAL-023 | B31: 3 | C31: Đăng ký dự án | D31: Phát sinh | E31: Gửi đăng ký không có BOM và không có file BOM | F31: Bị chặn "Bắt buộc phải nhập Danh mục BOM…"
A32: SAL-024 | B32: 3 | C32: Đăng ký dự án | D32: Phát sinh | E32: Dự án Fortinet không nhập Net to FTN hoặc nhập 0 | F32: Bị chặn
A33: SAL-025 | B33: 3 | C33: Đăng ký dự án | D33: Phát sinh | E33: Đăng ký trùng dự án đã có | F33: Cảnh báo trùng, hiện Sales đã đăng ký trước
A34: SAL-026 | B34: 3 | C34: Đăng ký dự án | D34: Phát sinh | E34: PM báo trùng → Sales phản hồi "Không trùng"; Sales khác thử phản hồi | F34: Dự án quay lại xử lý; chỉ Sales phụ trách được phản hồi
A35: SAL-027 | B35: 3 | C35: Đăng ký dự án | D35: Phát sinh | E35: PM trả "Thiếu thông tin" → Sales sửa, gửi lại | F35: Log ghi "gửi đăng ký lại (lần 2)"
A36: SAL-028 | B36: 3 | C36: Đăng ký dự án | D36: Phát sinh | E36: PM bấm nhắc Hãng | F36: SLA được gia hạn, có log
A37: SAL-029 | B37: 3 | C37: Đăng ký dự án | D37: Phát sinh | E37: Hãng từ chối → Sales nhân bản dự án | F37: Dự án cũ khóa sửa; bản nhân bản yêu cầu chọn Hãng mới
A38: SAL-030 | B38: 3 | C38: Đăng ký dự án | D38: Phát sinh | E38: Hãng gửi báo giá nhiều lần; xóa 1 phiên bản | F38: Có v1, v2…; xóa 1 bản không ảnh hưởng bản khác
A39: SAL-031 | B39: 3 | C39: Đăng ký dự án | D39: Phát sinh | E39: Thêm P.I.C phụ / người theo dõi | F39: Họ nhận thông báo và thấy dự án
A40: BƯỚC 4: LẬP BÁO GIÁ, GỬI KHÁCH
A41: SAL-032 | B41: 4 | C41: Báo giá | D41: Luồng chính | E41: Tạo báo giá: khách, P.I.C, sản phẩm từ catalog / bảng giá, chiết khấu, VAT | F41: Tổng tiền tính đúng
...

Sheet 2. Sales Manager
A1: CHECKLIST NGHIỆM THU – SALES MANAGER (TRƯỞNG PHÒNG KINH DOANH)
A2: Tài khoản test: Sales Manager; 2 Sales Staff trong nhóm của Sales Manager; 1 Sales Staff ở nhóm khác (để thử phạm vi xem)
A3: Sales Manager quản lý một nhóm Sales: xem toàn bộ dữ liệu của nhóm, xác nhận hoạt động gặp khách, phân P.I.C phụ và tỷ lệ chia margin, rà P&L và gửi duyệt thay Sales, đôn đốc công nợ. Sales Manager KHÔNG duyệt P&L — P&L do Legal (cấp 1) rồi BOD (cấp 2) duyệt. Theo code, Sales Manager cũng được duyệt yêu cầu đặt hàng như Admin. → Workflow từng bước (ai làm, vào menu nào, kết quả) xem ở sheet "Workflow". Cột "Bước" dưới đây khớp số bước trong Workflow.
A5: Mã TC | B5: Bước | C5: Chức năng | D5: Loại | E5: Tình huống / Thao tác | F5: Kết quả mong đợi | G5: Người test | H5: Ngày test | I5: Kết quả | J5: Kết quả thực tế / Mô tả lỗi (bắt buộc khi Không đạt / Bị chặn) | K5: Mức độ lỗi | L5: Bằng chứng (ảnh, mã chứng từ, tài khoản) | M5: Dev phản hồi | N5: Trạng thái xử lý | O5: Ghi chú
A6: BƯỚC 1: XEM DỮ LIỆU CỦA NHÓM
A7: SM-001 | B7: 1 | C7: Phạm vi xem | D7: Luồng chính | E7: Đăng nhập Sales Manager, mở Khách hàng / Báo giá / Đơn hàng bán | F7: Thấy dữ liệu của mình và các thành viên trong nhóm
A8: SM-002 | B8: 1 | C8: Phạm vi xem | D8: Phát sinh | E8: Mở link đơn hàng / báo giá của Sales ở nhóm khác | F8: Không thấy hoặc bị chặn
A9: SM-003 | B9: 1 | C9: Phạm vi xem | D9: Phát sinh | E9: Thêm 1 Sales mới vào nhóm (Phân nhóm), mở lại danh sách | F9: Thấy thêm dữ liệu của người mới
A10: BƯỚC 2: XÁC NHẬN HOẠT ĐỘNG GẶP KHÁCH
A11: SM-004 | B11: 2 | C11: Xác nhận hoạt động | D11: Luồng chính | E11: Sales tạo hoạt động trình bày giải pháp → Sales Manager xác nhận | F11: Trạng thái "Đã xác nhận", Sales nhận thông báo; sau đó Sales chuyển Đang thực hiện / Hoàn thành được
A12: SM-005 | B12: 2 | C12: Xác nhận hoạt động | D12: Luồng chính | E12: Xác nhận hoạt động có quà: chọn vật phẩm MKT và số lượng | F12: Tồn vật phẩm giảm, quà "Đã duyệt", Marketing nhận ticket chuẩn bị quà
A13: SM-006 | B13: 2 | C13: Xác nhận hoạt động | D13: Luồng chính | E13: Xác nhận hoạt động cần kỹ sư: chọn kỹ sư đi cùng | F13: Ticket Kỹ thuật được tạo cho kỹ sư đó
A14: SM-007 | B14: 2 | C14: Xác nhận hoạt động | D14: Phát sinh | E14: Sales thường tự xác nhận hoạt động của mình | F14: Bị chặn "Chỉ BOD/Manager mới có quyền phê duyệt & xác nhận hoạt động cơ hội này."
A15: SM-008 | B15: 2 | C15: Xác nhận hoạt động | D15: Phát sinh | E15: Sales chuyển hoạt động chưa xác nhận sang Hoàn thành (kể cả loại cafe, không quà) | F15: Bị chặn "Hoạt động cần được BOD/Manager xác nhận trước khi đánh dấu hoàn thành."
A16: SM-009 | B16: 2 | C16: Xác nhận hoạt động | D16: Phát sinh | E16: Sales chuyển hoạt động trình bày giải pháp chưa xác nhận sang Đang thực hiện | F16: Bị chặn "Đợt trình bày/hoạt động phối hợp cần được BOD/Manager phê duyệt…"
A17: BƯỚC 3: PHÂN P.I.C PHỤ
A18: SM-010 | B18: 3 | C18: P.I.C phụ | D18: Luồng chính | E18: Gán P.I.C phụ cho dự án của Sales cùng phòng ban | F18: P.I.C phụ nhận thông báo, thấy dự án
A19: SM-011 | B19: 3 | C19: P.I.C phụ | D19: Phát sinh | E19: Gán P.I.C phụ cho dự án của Sales khác phòng ban | F19: Bị chặn (Sales Manager chỉ sửa dự án cùng phòng ban — kiểm cột Phòng ban của nhân viên)
A20: SM-012 | B20: 3 | C20: P.I.C phụ | D20: Luồng chính | E20: Gán P.I.C phụ cho đơn hàng, chọn chia theo %: 60 / 40 | F20: Lưu đúng 60% / 40%; báo cáo doanh số nhân viên chia đúng
A21: SM-013 | B21: 3 | C21: P.I.C phụ | D21: Luồng chính | E21: Đổi cách chia sang "người phụ 100%", rồi bỏ P.I.C phụ | F21: Người phụ hưởng 100%; bỏ P.I.C phụ thì quay về người chính 100%
A22: SM-014 | B22: 3 | C22: P.I.C phụ | D22: Phát sinh | E22: Sales thường gán P.I.C phụ cho dự án không phải của mình | F22: Bị chặn
A23: SM-015 | B23: 3 | C23: P.I.C phụ | D23: Phát sinh | E23: Chọn P.I.C phụ trùng người tạo đơn (đơn hàng) / trùng người phụ trách chính (dự án) | F23: Đơn: "Người phụ trách thứ 2 không được trùng với Người tạo đơn." Dự án: "… trùng với Người phụ trách chính."
A24: SM-016 | B24: 3 | C24: P.I.C phụ | D24: Phát sinh | E24: BOD gán P.I.C phụ cho dự án | F24: Bị chặn (BOD không sửa dự án)
A25: BƯỚC 4: RÀ P&L, GỬI DUYỆT THAY SALES
A26: SM-017 | B26: 4 | C26: P&L | D26: Luồng chính | E26: Mở P&L đơn của thành viên, bấm Gửi duyệt thay | F26: "Chờ duyệt", Legal nhận thông báo cấp 1
A27: SM-018 | B27: 4 | C27: P&L | D27: Luồng chính | E27: Theo dõi đơn đang chờ duyệt | F27: Thấy đơn đang ở cấp nào (Legal / BOD) và lịch sử duyệt
A28: SM-019 | B28: 4 | C28: P&L | D28: Phát sinh | E28: Đơn bị Legal / BOD yêu cầu sửa hoặc từ chối | F28: Sales Manager và Sales đều thấy lý do
A29: SM-020 | B29: 4 | C29: P&L | D29: Phát sinh | E29: Sales Manager tìm nút duyệt P&L | F29: Không có nút duyệt (không phải cấp duyệt)
A30: BƯỚC 5: DUYỆT YÊU CẦU ĐẶT HÀNG (KHI ĐƯỢC GIAO)
A31: SM-021 | B31: 5 | C31: Yêu cầu đặt hàng | D31: Luồng chính | E31: Yêu cầu "Chờ Admin duyệt" của nhóm → Sales Manager duyệt | F31: "Đã gửi", PO Team thấy ở Duyệt yêu cầu (PR), Sales nhận thông báo
A32: SM-022 | B32: 5 | C32: Yêu cầu đặt hàng | D32: Phát sinh | E32: Trả về kèm lý do (thiếu thông tin / sửa P&L) | F32: Sales nhận lý do, sửa và gửi lại được
A33: SM-023 | B33: 5 | C33: Yêu cầu đặt hàng | D33: Phát sinh | E33: Duyệt yêu cầu không ở trạng thái Chờ Admin duyệt | F33: Bị chặn
A34: BƯỚC 6: UNC & CÔNG NỢ CỦA NHÓM
A35: SM-024 | B35: 6 | C35: UNC & công nợ | D35: Luồng chính | E35: Upload UNC thay Sales cho đơn của nhóm (đơn chưa xuất hóa đơn) | F35: Kế toán nhận thông báo xác nhận
A36: SM-025 | B36: 6 | C36: UNC & công nợ | D36: Phát sinh | E36: Upload UNC cho đơn đã xuất hóa đơn chính thức | F36: Bị chặn "Đơn hàng đã xuất hóa đơn. Việc theo dõi và thu hồi công nợ sau khi xuất hóa đơn do Kế toán phụ trách."
A37: SM-026 | B37: 6 | C37: UNC & công nợ | D37: Phát sinh | E37: Sales ngoài nhóm upload UNC cho đơn không phải của mình | F37: Bị chặn "Chỉ Sales phụ trách đơn hàng hoặc quản lý Sales…"
A38: SM-027 | B38: 6 | C38: UNC & công nợ | D38: Luồng chính | E38: Mở Công nợ khách hàng, lọc nợ quá hạn | F38: Đúng số liệu, đúng phạm vi nhóm
A39: BƯỚC 7: BÁO CÁO NHÓM
A40: SM-028 | B40: 7 | C40: Báo cáo | D40: Luồng chính | E40: Báo cáo tần suất gặp và báo cáo bán hàng, lọc từng thành viên | F40: Khớp hoạt động và đơn hàng của từng người
A41: SM-029 | B41: 7 | C41: Báo cáo | D41: Luồng chính | E41: Mở Dashboard | F41: Thấy số liệu đúng phạm vi nhóm

Sheet 3. Legal
A1: CHECKLIST NGHIỆM THU – LEGAL TEAM (PHÁP CHẾ) – DUYỆT CẤP 1 HỢP ĐỒNG & P&L
A2: Tài khoản test: Legal Team; Sales Staff (gửi duyệt); BOD (duyệt cấp 2)
A3: Legal là cấp duyệt 1 của mọi đơn hàng bán, trước BOD. Legal kiểm tra hợp đồng mua bán (HĐMB) và bảng P&L, rồi duyệt, yêu cầu Sales chỉnh sửa, hoặc từ chối. Legal không sửa đơn. Quy trình cấu hình ở Hệ thống › Quy trình duyệt: "Quy trình duyệt P&L & Hợp đồng bán hàng" – Cấp 1 Legal Team → Cấp 2 BOD. → Workflow từng bước (ai làm, vào menu nào, kết quả) xem ở sheet "Workflow". Cột "Bước" dưới đây khớp số bước trong Workflow.
A5: Mã TC | B5: Bước | C5: Chức năng | D5: Loại | E5: Tình huống / Thao tác | F5: Kết quả mong đợi | G5: Người test | H5: Ngày test | I5: Kết quả | J5: Kết quả thực tế / Mô tả lỗi (bắt buộc khi Không đạt / Bị chặn) | K5: Mức độ lỗi | L5: Bằng chứng (ảnh, mã chứng từ, tài khoản) | M5: Dev phản hồi | N5: Trạng thái xử lý | O5: Ghi chú
A6: BƯỚC 1: NHẬN ĐƠN CHỜ DUYỆT
A7: LEG-001 | B7: 1 | C7: Nhận đơn | D7: Luồng chính | E7: Sales gửi duyệt P&L | F7: Legal nhận thông báo, đơn có trong danh sách chờ duyệt của Legal
A8: LEG-002 | B8: 1 | C8: Nhận đơn | D8: Phát sinh | E8: BOD mở đơn đang chờ Legal | F8: Hiện đang ở cấp 1 – Legal; BOD chưa duyệt cấp 2 được (nếu quy định cho BOD duyệt vượt cấp thì ghi rõ)
A9: LEG-003 | B9: 1 | C9: Nhận đơn | D9: Phát sinh | E9: Tắt quy trình duyệt P&L rồi Sales gửi duyệt | F9: Đơn chuyển chờ duyệt thủ công, không lỗi trang
A10: BƯỚC 2: THẨM ĐỊNH HỒ SƠ
A11: LEG-004 | B11: 2 | C11: Thẩm định | D11: Luồng chính | E11: Legal mở SO: thông tin khách, điều khoản, file đính kèm, bảng P&L | F11: Xem đủ, tải / xem trước file được
A12: LEG-005 | B12: 2 | C12: Thẩm định | D12: Phát sinh | E12: Legal thử sửa giá / chi phí trên P&L | F12: Không sửa được (chỉ xem)
A13: LEG-006 | B13: 2 | C13: Thẩm định | D13: Phát sinh | E13: Đơn không có file hợp đồng đính kèm | F13: Legal thấy rõ là thiếu, dùng Yêu cầu chỉnh sửa để Sales bổ sung
A14: BƯỚC 3: RA QUYẾT ĐỊNH
A15: LEG-007 | B15: 3 | C15: Quyết định | D15: Luồng chính | E15: Legal duyệt kèm ghi chú | F15: Cấp 1 Đã duyệt, BOD nhận thông báo cấp 2, Sales thấy tiến độ
A16: LEG-008 | B16: 3 | C16: Quyết định | D16: Luồng chính | E16: Legal yêu cầu chỉnh sửa kèm lý do | F16: P&L "Yêu cầu chỉnh sửa", Sales nhận lý do và sửa được
A17: LEG-009 | B17: 3 | C17: Quyết định | D17: Luồng chính | E17: Legal từ chối kèm lý do | F17: "Từ chối (P&L)", Sales nhận thông báo kèm lý do
A18: LEG-010 | B18: 3 | C18: Quyết định | D18: Phát sinh | E18: Từ chối / yêu cầu sửa mà không nhập lý do | F18: Bị chặn hoặc bắt buộc nhập lý do
A19: LEG-011 | B19: 3 | C19: Quyết định | D19: Phát sinh | E19: Tài khoản legal không được cấp quyền approve_sales | F19: Không thấy nút duyệt / bị chặn
A20: BƯỚC 4: THEO DÕI SAU DUYỆT
A21: LEG-012 | B21: 4 | C21: Sau duyệt | D21: Luồng chính | E21: Sales sửa xong gửi lại | F21: Đơn quay về cấp 1 Legal, lịch sử giữ lần duyệt trước
A22: LEG-013 | B22: 4 | C22: Sau duyệt | D22: Luồng chính | E22: BOD duyệt cấp 2 sau Legal | F22: P&L Đã duyệt, Sales tạo được yêu cầu đặt hàng
A23: LEG-014 | B23: 4 | C23: Sau duyệt | D23: Phát sinh | E23: Legal mở đơn đã duyệt hoàn tất | F23: Chỉ xem, không duyệt lại
A24: LEG-015 | B24: 4 | C24: Sau duyệt | D24: Luồng chính | E24: Legal mở phiếu xuất kho của đơn | F24: Xem được

Sheet 4. BOD
A1: CHECKLIST NGHIỆM THU – BAN GIÁM ĐỐC (DIRECTOR)
A2: Tài khoản test: BOD; Sales Staff; Legal Team; Marketing; Order Management
A3: BOD là cấp duyệt cuối: duyệt P&L cấp 2 sau Legal, quyết định ngoại lệ thanh toán (cho đặt hàng / xuất hàng khi khách chưa trả), mở lại P&L đã duyệt, duyệt các khoản chi Marketing. BOD theo dõi kinh doanh qua Dashboard. → Workflow từng bước (ai làm, vào menu nào, kết quả) xem ở sheet "Workflow". Cột "Bước" dưới đây khớp số bước trong Workflow.
A5: Mã TC | B5: Bước | C5: Chức năng | D5: Loại | E5: Tình huống / Thao tác | F5: Kết quả mong đợi | G5: Người test | H5: Ngày test | I5: Kết quả | J5: Kết quả thực tế / Mô tả lỗi (bắt buộc khi Không đạt / Bị chặn) | K5: Mức độ lỗi | L5: Bằng chứng (ảnh, mã chứng từ, tài khoản) | M5: Dev phản hồi | N5: Trạng thái xử lý | O5: Ghi chú
A6: BƯỚC 1: DUYỆT P&L CẤP 2
A7: BOD-001 | B7: 1 | C7: P&L cấp 2 | D7: Luồng chính | E7: Legal đã duyệt cấp 1 → BOD duyệt | F7: P&L Đã duyệt, đơn Đã duyệt, Sales nhận thông báo
A8: BOD-002 | B8: 1 | C8: P&L cấp 2 | D8: Luồng chính | E8: BOD yêu cầu chỉnh sửa / từ chối kèm lý do | F8: Sales nhận lý do; gửi lại thì đi lại từ Legal cấp 1
A9: BOD-003 | B9: 1 | C9: P&L cấp 2 | D9: Phát sinh | E9: Badge / chuông khi có đơn chờ cấp 2; duyệt xong | F9: Số việc chờ giảm
A10: BƯỚC 2: NGOẠI LỆ THANH TOÁN & ỦY QUYỀN
A11: BOD-004 | B11: 2 | C11: Ngoại lệ | D11: Luồng chính | E11: Duyệt ngoại lệ toàn đơn (preload) | F11: Đặt hàng / xuất kho được dù chưa thu
A12: BOD-005 | B12: 2 | C12: Ngoại lệ | D12: Luồng chính | E12: Duyệt ngoại lệ 1 đợt | F12: Chỉ mở khóa giai đoạn của đợt đó
A13: BOD-006 | B13: 2 | C13: Ngoại lệ | D13: Luồng chính | E13: Ủy quyền cho người khác duyệt ngoại lệ, sau đó thu hồi | F13: Người được ủy quyền nhận thông báo, duyệt được; sau thu hồi thì không duyệt được
A14: BOD-007 | B14: 2 | C14: Ngoại lệ | D14: Phát sinh | E14: Người không phải BOD bấm ủy quyền | F14: Bị chặn "Chỉ BOD mới có quyền ủy quyền…"
A15: BƯỚC 3: MỞ LẠI P&L ĐÃ DUYỆT
A16: BOD-008 | B16: 3 | C16: Mở lại P&L | D16: Luồng chính | E16: Duyệt yêu cầu mở lại P&L | F16: P&L mở cho Sales sửa
A17: BOD-009 | B17: 3 | C17: Mở lại P&L | D17: Luồng chính | E17: Từ chối yêu cầu mở lại | F17: P&L giữ khóa, Sales nhận lý do
A18: BƯỚC 4: DUYỆT VIỆC MARKETING / CƠ HỘI
A19: BOD-010 | B19: 4 | C19: Marketing / cơ hội | D19: Luồng chính | E19: Xác nhận hoạt động trình bày giải pháp | F19: Sales hoàn thành được hoạt động
A20: BOD-011 | B20: 4 | C20: Marketing / cơ hội | D20: Luồng chính | E20: Duyệt / từ chối quà tặng của cơ hội | F20: Duyệt: Marketing nhận việc. Từ chối: Sales nhận lý do
A21: BOD-012 | B21: 4 | C21: Marketing / cơ hội | D21: Luồng chính | E21: Duyệt ngân sách sự kiện sau Order Management duyệt cấp 1 | F21: Sự kiện Đã duyệt
A22: BOD-013 | B22: 4 | C22: Marketing / cơ hội | D22: Luồng chính | E22: Duyệt vật phẩm mới, chi phí, đi công tác | F22: Đúng như sheet Marketing
A23: BƯỚC 5: DASHBOARD & BÁO CÁO
A24: BOD-014 | B24: 5 | C24: Dashboard | D24: Luồng chính | E24: Dashboard: lọc kỳ / phòng / nhân viên, drill-down | F24: Số liệu khớp danh sách gốc
A25: BOD-015 | B25: 5 | C25: Dashboard | D25: Luồng chính | E25: Dashboard hoạt động kinh doanh: làm mới, xuất file | F25: Chạy được, file đúng
A26: BOD-016 | B26: 5 | C26: Báo cáo | D26: Luồng chính | E26: Báo cáo bán hàng / margin, mua hàng, tần suất gặp, dự án | F26: Số liệu khớp
A27: BOD-017 | B27: 5 | C27: Báo cáo | D27: Phát sinh | E27: Chọn kỳ không có dữ liệu | F27: Hiển thị 0 / trống, không lỗi
A28: BƯỚC 6: TỔNG DOANH SỐ
A29: BOD-018 | B29: 6 | C29: Tổng doanh số | D29: Luồng chính | E29: BOD xóa 1 dòng tổng doanh số | F29: Xóa được; tài khoản khác bị chặn

Sheet 5. Admin duyệt đơn
A1: CHECKLIST NGHIỆM THU – ADMIN KIỂM SOÁT ĐƠN HÀNG – DUYỆT YÊU CẦU ĐẶT HÀNG & ĐỀ XUẤT XUẤT KHO
A2: Tài khoản test: Admin (người duyệt); Sales Staff; Finance Team; Nhân viên kho. Lưu ý quyền theo code: duyệt yêu cầu đặt hàng = Admin, Order Management, Quản trị viên, BOD, PO Manager, Sales Manager; duyệt xuất kho = Quản trị viên, Admin, PO Manager hoặc vai trò có quyền approve_exports (Order Management đang có quyền này nên duyệt xuất kho được).
A3: Admin là chốt kiểm tra hồ sơ ở hai khâu. Khâu đặt hàng: trước khi PO Team đặt Hãng, Admin xác nhận đơn đã duyệt P&L và đủ giấy tờ (hợp đồng / PO khách, BOM, thông tin End User…). Khâu xuất hàng: trước khi Kho giao, Admin xác nhận hàng đã đủ, khách đã thanh toán đúng điều kiện và giấy tờ giao hàng đã sẵn sàng. Thiếu gì thì trả về cho Sales kèm lý do cụ thể. → Workflow từng bước (ai làm, vào menu nào, kết quả) xem ở sheet "Workflow". Cột "Bước" dưới đây khớp số bước trong Workflow.
A5: Mã TC | B5: Bước | C5: Chức năng | D5: Loại | E5: Tình huống / Thao tác | F5: Kết quả mong đợi | G5: Người test | H5: Ngày test | I5: Kết quả | J5: Kết quả thực tế / Mô tả lỗi (bắt buộc khi Không đạt / Bị chặn) | K5: Mức độ lỗi | L5: Bằng chứng (ảnh, mã chứng từ, tài khoản) | M5: Dev phản hồi | N5: Trạng thái xử lý | O5: Ghi chú
A6: BƯỚC 1: NHẬN YÊU CẦU ĐẶT HÀNG
A7: OAD-001 | B7: 1 | C7: Nhận yêu cầu | D7: Luồng chính | E7: Sales gửi yêu cầu đặt hàng | F7: Admin nhận thông báo, badge tăng, yêu cầu ở "Chờ Admin duyệt"
A8: BƯỚC 2: KIỂM TRA HỒ SƠ ĐẶT HÀNG
A9: OAD-002 | B9: 2 | C9: Kiểm tra hồ sơ | D9: Luồng chính | E9: Mở yêu cầu: xem P&L, file đính kèm, các dòng hàng, End User, POS-ID | F9: Đủ thông tin để kiểm; xem trước / tải file được
A10: BƯỚC 3: DUYỆT / TRẢ VỀ YÊU CẦU ĐẶT HÀNG
A11: OAD-003 | B11: 3 | C11: Duyệt đặt hàng | D11: Luồng chính | E11: Hồ sơ đủ → Duyệt | F11: "Đã gửi"; Sales nhận "đã được Admin duyệt"; PO Team thấy ở Duyệt yêu cầu (PR)
A12: OAD-004 | B12: 3 | C12: Duyệt đặt hàng | D12: Phát sinh | E12: Thiếu file hợp đồng / PO khách → trả về Thiếu thông tin kèm lý do | F12: Sales nhận lý do, mở đúng yêu cầu để bổ sung, gửi lại → về Chờ Admin duyệt
A13: OAD-005 | B13: 3 | C13: Duyệt đặt hàng | D13: Phát sinh | E13: Giá vốn / chi phí sai → trả về chỉnh P&L | F13: P&L "Cần sửa"; sau khi sửa phải qua Legal và BOD lại
A14: OAD-006 | B14: 3 | C14: Duyệt đặt hàng | D14: Phát sinh | E14: Trả về mà không nhập lý do | F14: Bị chặn (bắt buộc lý do)
A15: OAD-007 | B15: 3 | C15: Duyệt đặt hàng | D15: Phát sinh | E15: Duyệt yêu cầu không ở Chờ Admin duyệt | F15: Bị chặn "Yêu cầu không ở trạng thái Chờ Admin duyệt."
A16: OAD-008 | B16: 3 | C16: Duyệt đặt hàng | D16: Phát sinh | E16: Tài khoản Sales Staff bấm duyệt yêu cầu đặt hàng | F16: Bị chặn "Bạn không có quyền…"
A17: OAD-009 | B17: 3 | C17: Duyệt đặt hàng | D17: Phát sinh | E17: Sales bổ sung rồi gửi lại | F17: Lịch sử ghi lần trả về và lần gửi lại
A18: BƯỚC 4: NHẬN ĐỀ XUẤT XUẤT KHO
A19: OAD-010 | B19: 4 | C19: Nhận đề xuất xuất | D19: Luồng chính | E19: Sales gửi đề xuất xuất kho | F19: Admin nhận "Đề xuất xuất kho mới"; Kho nhận thông báo chuẩn bị hàng
A20: OAD-011 | B20: 4 | C20: Nhận đề xuất xuất | D20: Phát sinh | E20: Hàng runrate mà Sales chỉ giữ thiếu suất, gửi đề xuất | F20: Không gửi được, báo "… chỉ đang giữ x/y"
A21: BƯỚC 5: KIỂM TRA ĐIỀU KIỆN XUẤT HÀNG
A22: OAD-012 | B22: 5 | C22: Kiểm tra xuất | D22: Luồng chính | E22: Mở phiếu xuất: xem SO, dòng xuất, số lượng, tình trạng thanh toán, hóa đơn | F22: Đủ thông tin để kiểm
A23: BƯỚC 6: DUYỆT / TỪ CHỐI XUẤT KHO
A24: OAD-013 | B24: 6 | C24: Duyệt xuất kho | D24: Luồng chính | E24: Duyệt phiếu khi đơn chưa có HĐ chính thức | F24: "Chờ KT xuất hóa đơn", Kế toán nhận thông báo
A25: OAD-014 | B25: 6 | C25: Duyệt xuất kho | D25: Luồng chính | E25: Duyệt phiếu khi đơn đã có HĐ chính thức | F25: Sẵn sàng xuất thực tế, Kho nhận thông báo
A26: OAD-015 | B26: 6 | C26: Duyệt xuất kho | D26: Phát sinh | E26: Đợt "trước xuất hàng" chưa được Kế toán xác nhận, bấm duyệt | F26: Bị chặn, liệt kê đợt còn thiếu
A27: OAD-016 | B27: 6 | C27: Duyệt xuất kho | D27: Phát sinh | E27: Đơn có ngoại lệ BOD cho xuất trước | F27: Duyệt được
A28: OAD-017 | B28: 6 | C28: Duyệt xuất kho | D28: Phát sinh | E28: Từ chối kèm lý do | F28: Phiếu về Bản nháp, Sales nhận lý do, sửa gửi lại được
A29: OAD-018 | B29: 6 | C29: Duyệt xuất kho | D29: Phát sinh | E29: Duyệt phiếu không ở Chờ Admin duyệt | F29: Bị chặn
A30: OAD-019 | B30: 6 | C30: Duyệt xuất kho | D30: Phát sinh | E30: Tài khoản không có quyền duyệt xuất (không phải Quản trị viên / Admin / PO Manager, không có quyền approve_exports, vd Sales Staff) | F30: Bị chặn
A31: OAD-020 | B31: 6 | C31: Duyệt xuất kho | D31: Luồng chính | E31: Tài khoản Order Management duyệt đề xuất xuất kho | F31: Duyệt được (vai trò này có quyền approve_exports)

Sheet 6. Order Management
A1: CHECKLIST NGHIỆM THU – ORDER MANAGEMENT – QUẢN LÝ ĐƠN HÀNG & ĐIỀU PHỐI PO TEAM
A2: Tài khoản test: Order Management; Sales Staff; PO Staff; Finance Team; Marketing. Cần chạy migration 2026_10_26_100000 trên server trước khi test sheet này
A3: Order Management (chị Bích) kiểm soát đơn hàng từ lúc Sales xin đặt hàng đến lúc xuất hàng, đồng thời điều phối PO Team. Vai trò này duyệt yêu cầu đặt hàng như Admin, tiếp nhận yêu cầu để PO Team gom đơn đặt Hãng, duyệt PO, duyệt đề xuất xuất kho và duyệt ngân sách Marketing cấp 1. Order Management xem được toàn bộ báo giá và đơn hàng của công ty. → Workflow từng bước (ai làm, vào menu nào, kết quả) xem ở sheet "Workflow". Cột "Bước" dưới đây khớp số bước trong Workflow.
A5: Mã TC | B5: Bước | C5: Chức năng | D5: Loại | E5: Tình huống / Thao tác | F5: Kết quả mong đợi | G5: Người test | H5: Ngày test | I5: Kết quả | J5: Kết quả thực tế / Mô tả lỗi (bắt buộc khi Không đạt / Bị chặn) | K5: Mức độ lỗi | L5: Bằng chứng (ảnh, mã chứng từ, tài khoản) | M5: Dev phản hồi | N5: Trạng thái xử lý | O5: Ghi chú
A6: BƯỚC 1: THEO DÕI TOÀN BỘ ĐƠN HÀNG
A7: OM-001 | B7: 1 | C7: Phạm vi xem | D7: Luồng chính | E7: Đăng nhập Order Management, mở Đơn hàng bán và Báo giá | F7: Thấy toàn bộ đơn / báo giá của công ty
A8: OM-002 | B8: 1 | C8: Phạm vi xem | D8: Luồng chính | E8: Kiểm menu Mua hàng | F8: Có Bảng giá, Duyệt yêu cầu (PR), Gom đơn cần đặt, Đơn hàng (Không PNL), Đặt hàng với hãng (PO), Báo cáo mua hàng; badge đếm đúng
A9: BƯỚC 2: DUYỆT YÊU CẦU ĐẶT HÀNG
A10: OM-003 | B10: 2 | C10: Duyệt đặt hàng | D10: Luồng chính | E10: Sales gửi yêu cầu đặt hàng | F10: Order Management nhận thông báo (cùng Admin, PO Manager)
A11: OM-004 | B11: 2 | C11: Duyệt đặt hàng | D11: Luồng chính | E11: Duyệt yêu cầu "Chờ Admin duyệt" từ màn Duyệt yêu cầu (PR) | F11: "Đã gửi", Sales nhận "đã được Admin duyệt"
A12: OM-005 | B12: 2 | C12: Duyệt đặt hàng | D12: Luồng chính | E12: Duyệt yêu cầu "Chờ Admin duyệt" từ màn chi tiết SO | F12: Có nút duyệt, kết quả như trên
A13: OM-006 | B13: 2 | C13: Duyệt đặt hàng | D13: Phát sinh | E13: Trả về Thiếu thông tin / trả về sửa P&L kèm lý do | F13: Sales nhận lý do; trả về P&L thì P&L mở lại
A14: OM-007 | B14: 2 | C14: Duyệt đặt hàng | D14: Phát sinh | E14: Sửa yêu cầu đặt hàng đã gửi (không ở nháp / thiếu thông tin) | F14: Sửa được (quyền quản lý), có lịch sử
A15: BƯỚC 3: TIẾP NHẬN YÊU CẦU CHO PO TEAM
A16: OM-008 | B16: 3 | C16: Tiếp nhận PR | D16: Luồng chính | E16: Tiếp nhận yêu cầu "Đã gửi" | F16: "Đang xử lý", dòng xuất hiện ở Gom đơn cần đặt
A17: OM-009 | B17: 3 | C17: Tiếp nhận PR | D17: Phát sinh | E17: Trả về khi tiếp nhận kèm lý do | F17: Sales nhận lý do, yêu cầu về "Thiếu thông tin"
A18: OM-010 | B18: 3 | C18: Tiếp nhận PR | D18: Luồng chính | E18: Sửa thông tin End User tại Duyệt yêu cầu (PR) | F18: Lưu được, đồng bộ về SO
A19: BƯỚC 4: GOM ĐƠN & ĐIỀU PHỐI PO TEAM
A20: OM-011 | B20: 4 | C20: Gom đơn | D20: Luồng chính | E20: Mở Gom đơn cần đặt, tạo PO nháp từ các dòng chờ | F20: Tạo được
A21: OM-012 | B21: 4 | C21: Gom đơn | D21: Luồng chính | E21: Tạo đơn nhanh ở Đơn hàng (Không PNL) | F21: Tạo được, dòng vào danh sách cần đặt
A22: BƯỚC 5: DUYỆT PO
A23: OM-013 | B23: 5 | C23: Duyệt PO | D23: Luồng chính | E23: PO Staff gửi duyệt PO → Order Management duyệt | F23: PO "Đã đặt", Sales nhận thông báo
A24: OM-014 | B24: 5 | C24: Duyệt PO | D24: Phát sinh | E24: Từ chối PO kèm lý do | F24: Người tạo nhận "PO … đã bị từ chối"
A25: OM-015 | B25: 5 | C25: Duyệt PO | D25: Luồng chính | E25: Hold / gỡ Hold PO | F25: Sales nhận thông báo kèm lý do
A26: BƯỚC 6: DUYỆT ĐỀ XUẤT XUẤT KHO
A27: OM-016 | B27: 6 | C27: Duyệt xuất kho | D27: Luồng chính | E27: Duyệt đề xuất xuất kho từ Kho hàng › Xuất kho | F27: Kết quả như sheet Admin duyệt đơn
A28: OM-017 | B28: 6 | C28: Duyệt xuất kho | D28: Luồng chính | E28: Mở SO có phiếu xuất "Chờ Admin duyệt" | F28: Có nút duyệt / từ chối ngay trên SO
A29: OM-018 | B29: 6 | C29: Duyệt xuất kho | D29: Phát sinh | E29: Đợt "trước xuất hàng" chưa được Kế toán xác nhận, bấm duyệt | F29: Bị chặn, liệt kê đợt còn thiếu
A30: BƯỚC 7: DUYỆT NGÂN SÁCH MARKETING CẤP 1
A31: OM-019 | B31: 7 | C31: Ngân sách MKT | D31: Luồng chính | E31: Marketing gửi duyệt sự kiện → Order Management duyệt cấp 1 | F31: Chuyển BOD duyệt cấp 2, BOD nhận thông báo
A32: OM-020 | B32: 7 | C32: Ngân sách MKT | D32: Phát sinh | E32: Từ chối kèm lý do | F32: Marketing nhận lý do, sửa và gửi lại được
A33: BƯỚC 8: BẢNG GIÁ NCC & BÁO CÁO
A34: OM-021 | B34: 8 | C34: Bảng giá & báo cáo | D34: Luồng chính | E34: Mở Báo cáo mua hàng, xuất Excel | F34: Số liệu khớp PO, file mở được
A35: OM-022 | B35: 8 | C35: Bảng giá & báo cáo | D35: Luồng chính | E35: Sửa nhà cung cấp, bảng giá NCC | F35: Lưu được
A36: OM-023 | B36: 8 | C36: Phân quyền | D36: Phát sinh | E36: Mở trang Vai trò, Quyền, Cài đặt | F36: Không có quyền / bị chặn

Sheet 7. Mua hàng
A1: CHECKLIST NGHIỆM THU – PHÒNG MUA HÀNG (PO TEAM)
A2: Tài khoản test: PO Staff (thao tác), PO Manager (duyệt PO), Admin (xóa PO, duyệt yêu cầu đặt hàng)
A3: Mua hàng biến yêu cầu đặt hàng của Sales thành đơn đặt Hãng / NCC (PO), theo dõi hàng trên đường về và xác nhận hàng đã nhận. Một PO có thể gom hàng của nhiều SO cùng Hãng. Khi PO nhận hàng, hệ thống tự tạo phiếu nhập kho cho Kho. → Workflow từng bước (ai làm, vào menu nào, kết quả) xem ở sheet "Workflow". Cột "Bước" dưới đây khớp số bước trong Workflow.
A5: Mã TC | B5: Bước | C5: Chức năng | D5: Loại | E5: Tình huống / Thao tác | F5: Kết quả mong đợi | G5: Người test | H5: Ngày test | I5: Kết quả | J5: Kết quả thực tế / Mô tả lỗi (bắt buộc khi Không đạt / Bị chặn) | K5: Mức độ lỗi | L5: Bằng chứng (ảnh, mã chứng từ, tài khoản) | M5: Dev phản hồi | N5: Trạng thái xử lý | O5: Ghi chú
A6: BƯỚC 1: NHÀ CUNG CẤP & BẢNG GIÁ NCC
A7: PUR-001 | B7: 1 | C7: Nhà cung cấp | D7: Luồng chính | E7: Tạo NCC đủ thông tin; cấu hình mẫu PO riêng | F7: Lưu thành công, mẫu PO áp dụng khi in PO của NCC này
A8: PUR-002 | B8: 1 | C8: Bảng giá NCC | D8: Luồng chính | E8: Import bảng giá Excel (Fortinet / Zyxel / QNAP / SonicWall / Perle) | F8: Tự nhận sheet, cột SKU, cột giá
A9: PUR-003 | B9: 1 | C9: Bảng giá NCC | D9: Luồng chính | E9: Xem trước và áp giá vào sản phẩm; cấu hình chiết khấu | F9: Báo số sản phẩm tạo mới / cập nhật
A10: PUR-004 | B10: 1 | C10: Nhà cung cấp | D10: Phát sinh | E10: Mã NCC trùng; thiếu email / chức vụ người liên hệ | F10: Báo "Mã nhà cung cấp này đã tồn tại" / báo bắt buộc
A11: PUR-005 | B11: 1 | C11: Nhà cung cấp | D11: Phát sinh | E11: Xóa NCC đã có báo giá / đơn đặt hàng / phiếu nhập | F11: Bị chặn, nêu rõ lý do
A12: PUR-006 | B12: 1 | C12: Bảng giá NCC | D12: Phát sinh | E12: File bảng giá trống / chỉ có tiêu đề / không có cột SKU hoặc cột giá | F12: Báo lỗi rõ, không import nửa chừng
A13: PUR-007 | B13: 1 | C13: Bảng giá NCC | D13: Phát sinh | E13: Chiết khấu < 0 hoặc > 100 | F13: Bị chặn
A14: PUR-008 | B14: 1 | C14: Bảng giá NCC | D14: Phát sinh | E14: Tắt bảng giá | F14: Không còn xuất hiện khi tra giá lúc báo giá
A15: BƯỚC 2: TIẾP NHẬN YÊU CẦU ĐẶT HÀNG
A16: PUR-009 | B16: 2 | C16: Tiếp nhận yêu cầu | D16: Luồng chính | E16: Duyệt yêu cầu đặt hàng đủ thông tin | F16: "Đang xử lý", dòng vào Gom đơn cần đặt
A17: PUR-010 | B17: 2 | C17: Tiếp nhận yêu cầu | D17: Phát sinh | E17: Trả yêu cầu thiếu thông tin kèm lý do | F17: "Thiếu thông tin", Sales nhận lý do
A18: PUR-011 | B18: 2 | C18: Tiếp nhận yêu cầu | D18: Phát sinh | E18: Trả đơn về Sales để chỉnh P&L | F18: SO mở lại P&L, ghi nhật ký
A19: PUR-012 | B19: 2 | C19: Tiếp nhận yêu cầu | D19: Phát sinh | E19: Sales sửa thông tin EU tại bước đặt hàng | F19: Bị chặn, chỉ PO Team được sửa
A20: BƯỚC 3: GOM ĐƠN, TẠO PO NHÁP
A21: PUR-013 | B21: 3 | C21: Gom đơn | D21: Luồng chính | E21: Mở Gom đơn cần đặt | F21: Đúng các dòng từ yêu cầu đã duyệt, kèm SO, Sales, số lượng còn cần đặt
A22: PUR-014 | B22: 3 | C22: Gom đơn | D22: Luồng chính | E22: Tạo PO nháp; gộp 2+ PO nháp cùng Hãng | F22: Các dòng về chung 1 PO
A23: PUR-015 | B23: 3 | C23: Gom đơn | D23: Luồng chính | E23: Sinh mã PO tự động, sửa mã thủ công | F23: Kiểm tra trùng mã
A24: PUR-016 | B24: 3 | C24: Gom đơn | D24: Phát sinh | E24: Gộp PO nháp khác Hãng hoặc chỉ chọn 1 PO | F24: Bị chặn
A25: PUR-017 | B25: 3 | C25: Gom đơn | D25: Phát sinh | E25: Đặt số lượng lớn hơn số còn cần đặt | F25: Bị chặn
A26: PUR-018 | B26: 3 | C26: Gom đơn | D26: Phát sinh | E26: Hủy 1 sản phẩm ở bước gom đơn kèm lý do; khôi phục lại | F26: Sales nhận thông báo, P&L mở lại; khôi phục được dòng đã hủy
A27: PUR-019 | B27: 3 | C27: Gom đơn | D27: Phát sinh | E27: Thông báo cho Sales về 1 sản phẩm (hết hàng, đổi model) | F27: Sales nhận thông báo
A28: BƯỚC 4: XÁC NHẬN & DUYỆT PO
A29: PUR-020 | B29: 4 | C29: Duyệt PO | D29: Luồng chính | E29: Xác nhận PO nháp → gửi duyệt → PO Manager duyệt | F29: "Đã đặt", Sales các SO liên quan nhận thông báo
A30: PUR-021 | B30: 4 | C30: Duyệt PO | D30: Luồng chính | E30: Xem trước / in / xuất Excel PO | F30: Đúng mẫu công ty và mẫu riêng NCC
A31: PUR-022 | B31: 4 | C31: Duyệt PO | D31: Phát sinh | E31: SO có đợt "trước đặt hàng" chưa được KT xác nhận, xác nhận PO nháp | F31: Bị chặn, liệt kê đợt còn thiếu
A32: PUR-023 | B32: 4 | C32: Duyệt PO | D32: Phát sinh | E32: PO Manager từ chối PO | F32: Người tạo nhận "PO … đã bị từ chối", sửa và gửi duyệt lại
A33: PUR-024 | B33: 4 | C33: Duyệt PO | D33: Phát sinh | E33: Sửa PO không ở trạng thái nháp, hoặc đã hoàn thành / hủy | F33: Bị chặn
A34: PUR-025 | B34: 4 | C34: Duyệt PO | D34: Phát sinh | E34: PO không gắn SO → liên kết thủ công với SO | F34: SO hiển thị tiến độ đặt hàng
A35: BƯỚC 5: GỬI HÃNG, THEO DÕI HÀNG VỀ
A36: PUR-026 | B36: 5 | C36: Gửi Hãng & theo dõi | D36: Luồng chính | E36: Gửi PO qua email cho NCC | F36: Email đến đúng địa chỉ, kèm file PO
A37: PUR-027 | B37: 5 | C37: Gửi Hãng & theo dõi | D37: Luồng chính | E37: NCC xác nhận → cập nhật ETD, ETA, vận đơn | F37: Sales thấy "Hãng đang sản xuất (ETD …)" / "Đang vận chuyển về VN (ETA …)"
A38: PUR-028 | B38: 5 | C38: Gửi Hãng & theo dõi | D38: Luồng chính | E38: Chuyển PO sang "Đang về" | F38: Toàn bộ / từng dòng đổi trạng thái
A39: PUR-029 | B39: 5 | C39: Gửi Hãng & theo dõi | D39: Luồng chính | E39: Upload license cho dòng license | F39: Sales nhận thông báo, xem / tải được
A40: PUR-030 | B40: 5 | C40: Gửi Hãng & theo dõi | D40: Phát sinh | E40: Hold PO kèm lý do; gỡ Hold | F40: Sales nhận thông báo; gỡ Hold thì tiếp tục xử lý
A41: PUR-031 | B41: 5 | C41: Gửi Hãng & theo dõi | D41: Phát sinh | E41: Cập nhật tracking cho PO đã hoàn thành / đã hủy | F41: Bị chặn
...

Sheet 8. Kho
A1: CHECKLIST NGHIỆM THU – KHO
A2: Tài khoản test: Nhân viên kho (thao tác), Quản lý kho (duyệt), Admin (duyệt đề xuất xuất kho, sửa Số PO phiếu nhập)
A3: Kho giữ số liệu tồn thật: mọi thiết bị theo dõi theo kho, Số PO và S/N. Phiếu nhập sinh từ PO của Mua hàng, phiếu xuất sinh từ đề xuất của Sales. Việc của Kho là kiểm hàng, ghi đúng S/N và bấm duyệt — chỉ khi Kho duyệt thì tồn mới tăng / giảm. Kho runrate là kho hàng có sẵn, Sales được xin giữ trước. → Workflow từng bước (ai làm, vào menu nào, kết quả) xem ở sheet "Workflow". Cột "Bước" dưới đây khớp số bước trong Workflow.
